Workbook
Name FirmwareList: Producción!$O$2:$O$52

Sheet Producción
A1: ID Tarjeta | B1: Nombre Tarjeta | C1: MAC Address (AUTO) | D1: Firmware PCB Principal | E1: Nombre Tarjeta Respaldo | F1: MAC Address Respaldo (AUTO) | G1: Firmware PCB Respaldo | H1: Botón R3 | I1: Semana Producción | J1: Fecha Proyectada Entrega | K1: Fecha Real Entrega | L1: Gabinete | N1: Semanas | O1: CATÁLOGO DE FIRMWARE PRINCIPAL | Q1: CATÁLOGO DE FIRMWARE RESPALDO
A2: 0011 | B2: =IF(A2="","","TQT-R1-V30-"&TEXT(VALUE(A2),"0000")) -> TQT-R1-V30-0011 | C2: =IF(B2="","",IFERROR(INDEX('Catálogo PCB'!$B$3:$B$102,MATCH(B2,'Catálogo PCB'!$A$3:$A$102,0))&"","")) | E2: TQT-R2-V30-0011 | F2: =IF(E2="","",IFERROR(INDEX('Catálogo PCB'!$G$3:$G$102,MATCH(E2,'Catálogo PCB'!$F$3:$F$102,0))&"","")) | N2: 2026-W01 | O2: 2 | Q2: 2
A3: 0012 | B3: =IF(A3="","","TQT-R1-V30-"&TEXT(VALUE(A3),"0000")) -> TQT-R1-V30-0012 | C3: =IF(B3="","",IFERROR(INDEX('Catálogo PCB'!$B$3:$B$102,MATCH(B3,'Catálogo PCB'!$A$3:$A$102,0))&"","")) | E3: TQT-R2-V30-0012 | F3: =IF(E3="","",IFERROR(INDEX('Catálogo PCB'!$G$3:$G$102,MATCH(E3,'Catálogo PCB'!$F$3:$F$102,0))&"","")) | N3: 2026-W02 | O3: 3.2 | Q3: 2.1
A4: 0013 | B4: =IF(A4="","","TQT-R1-V30-"&TEXT(VALUE(A4),"0000")) -> TQT-R1-V30-0013 | C4: =IF(B4="","",IFERROR(INDEX('Catálogo PCB'!$B$3:$B$102,MATCH(B4,'Catálogo PCB'!$A$3:$A$102,0))&"","")) | E4: TQT-R2-V30-0013 | F4: =IF(E4="","",IFERROR(INDEX('Catálogo PCB'!$G$3:$G$102,MATCH(E4,'Catálogo PCB'!$F$3:$F$102,0))&"","")) | N4: 2026-W03 | O4: 3.3
A5: 0014 | B5: =IF(A5="","","TQT-R1-V30-"&TEXT(VALUE(A5),"0000")) -> TQT-R1-V30-0014 | C5: =IF(B5="","",IFERROR(INDEX('Catálogo PCB'!$B$3:$B$102,MATCH(B5,'Catálogo PCB'!$A$3:$A$102,0))&"","")) | E5: TQT-R2-V30-0014 | F5: =IF(E5="","",IFERROR(INDEX('Catálogo PCB'!$G$3:$G$102,MATCH(E5,'Catálogo PCB'!$F$3:$F$102,0))&"","")) | N5: 2026-W04 | O5: 4.0
A6: 0015 | B6: =IF(A6="","","TQT-R1-V30-"&TEXT(VALUE(A6),"0000")) -> TQT-R1-V30-0015 | C6: =IF(B6="","",IFERROR(INDEX('Catálogo PCB'!$B$3:$B$102,MATCH(B6,'Catálogo PCB'!$A$3:$A$102,0))&"","")) | E6: TQT-R2-V30-0015 | F6: =IF(E6="","",IFERROR(INDEX('Catálogo PCB'!$G$3:$G$102,MATCH(E6,'Catálogo PCB'!$F$3:$F$102,0))&"","")) | N6: 2026-W05 | O6: 4.1
A7: 0016 | B7: =IF(A7="","","TQT-R1-V30-"&TEXT(VALUE(A7),"0000")) -> TQT-R1-V30-0016 | C7: =IF(B7="","",IFERROR(INDEX('Catálogo PCB'!$B$3:$B$102,MATCH(B7,'Catálogo PCB'!$A$3:$A$102,0))&"","")) | E7: TQT-R2-V30-0016 | F7: =IF(E7="","",IFERROR(INDEX('Catálogo PCB'!$G$3:$G$102,MATCH(E7,'Catálogo PCB'!$F$3:$F$102,0))&"","")) | N7: 2026-W06 | O7: 4.2
A8: 0017 | B8: =IF(A8="","","TQT-R1-V30-"&TEXT(VALUE(A8),"0000")) -> TQT-R1-V30-0017 | C8: =IF(B8="","",IFERROR(INDEX('Catálogo PCB'!$B$3:$B$102,MATCH(B8,'Catálogo PCB'!$A$3:$A$102,0))&"","")) | E8: TQT-R2-V30-0017 | F8: =IF(E8="","",IFERROR(INDEX('Catálogo PCB'!$G$3:$G$102,MATCH(E8,'Catálogo PCB'!$F$3:$F$102,0))&"","")) | N8: 2026-W07
A9: 0019 | B9: =IF(A9="","","TQT-R1-V30-"&TEXT(VALUE(A9),"0000")) -> TQT-R1-V30-0019 | C9: =IF(B9="","",IFERROR(INDEX('Catálogo PCB'!$B$3:$B$102,MATCH(B9,'Catálogo PCB'!$A$3:$A$102,0))&"","")) | E9: TQT-R2-V30-0019 | F9: =IF(E9="","",IFERROR(INDEX('Catálogo PCB'!$G$3:$G$102,MATCH(E9,'Catálogo PCB'!$F$3:$F$102,0))&"","")) | N9: 2026-W08
A10: 0020 | B10: =IF(A10="","","TQT-R1-V30-"&TEXT(VALUE(A10),"0000")) -> TQT-R1-V30-0020 | C10: =IF(B10="","",IFERROR(INDEX('Catálogo PCB'!$B$3:$B$102,MATCH(B10,'Catálogo PCB'!$A$3:$A$102,0))&"","")) | E10: TQT-R2-V30-0020 | F10: =IF(E10="","",IFERROR(INDEX('Catálogo PCB'!$G$3:$G$102,MATCH(E10,'Catálogo PCB'!$F$3:$F$102,0))&"","")) | N10: 2026-W09
A11: 0021 | B11: =IF(A11="","","TQT-R1-V30-"&TEXT(VALUE(A11),"0000")) -> TQT-R1-V30-0021 | C11: =IF(B11="","",IFERROR(INDEX('Catálogo PCB'!$B$3:$B$102,MATCH(B11,'Catálogo PCB'!$A$3:$A$102,0))&"","")) | E11: TQT-R2-V30-0021 | F11: =IF(E11="","",IFERROR(INDEX('Catálogo PCB'!$G$3:$G$102,MATCH(E11,'Catálogo PCB'!$F$3:$F$102,0))&"","")) | N11: 2026-W10
A12: 0022 | B12: =IF(A12="","","TQT-R1-V30-"&TEXT(VALUE(A12),"0000")) -> TQT-R1-V30-0022 | C12: =IF(B12="","",IFERROR(INDEX('Catálogo PCB'!$B$3:$B$102,MATCH(B12,'Catálogo PCB'!$A$3:$A$102,0))&"","")) | E12: TQT-R2-V30-0022 | F12: =IF(E12="","",IFERROR(INDEX('Catálogo PCB'!$G$3:$G$102,MATCH(E12,'Catálogo PCB'!$F$3:$F$102,0))&"","")) | N12: 2026-W11
A13: 0023 | B13: =IF(A13="","","TQT-R1-V30-"&TEXT(VALUE(A13),"0000")) -> TQT-R1-V30-0023 | C13: =IF(B13="","",IFERROR(INDEX('Catálogo PCB'!$B$3:$B$102,MATCH(B13,'Catálogo PCB'!$A$3:$A$102,0))&"","")) | E13: TQT-R2-V30-0023 | F13: =IF(E13="","",IFERROR(INDEX('Catálogo PCB'!$G$3:$G$102,MATCH(E13,'Catálogo PCB'!$F$3:$F$102,0))&"","")) | N13: 2026-W12
A14: 0024 | B14: =IF(A14="","","TQT-R1-V30-"&TEXT(VALUE(A14),"0000")) -> TQT-R1-V30-0024 | C14: =IF(B14="","",IFERROR(INDEX('Catálogo PCB'!$B$3:$B$102,MATCH(B14,'Catálogo PCB'!$A$3:$A$102,0))&"","")) | E14: TQT-R2-V30-0024 | F14: =IF(E14="","",IFERROR(INDEX('Catálogo PCB'!$G$3:$G$102,MATCH(E14,'Catálogo PCB'!$F$3:$F$102,0))&"","")) | N14: 2026-W13
A15: 0025 | B15: =IF(A15="","","TQT-R1-V30-"&TEXT(VALUE(A15),"0000")) -> TQT-R1-V30-0025 | C15: =IF(B15="","",IFERROR(INDEX('Catálogo PCB'!$B$3:$B$102,MATCH(B15,'Catálogo PCB'!$A$3:$A$102,0))&"","")) | E15: TQT-R2-V30-0025 | F15: =IF(E15="","",IFERROR(INDEX('Catálogo PCB'!$G$3:$G$102,MATCH(E15,'Catálogo PCB'!$F$3:$F$102,0))&"","")) | N15: 2026-W14
A16: 0026 | B16: =IF(A16="","","TQT-R1-V30-"&TEXT(VALUE(A16),"0000")) -> TQT-R1-V30-0026 | C16: =IF(B16="","",IFERROR(INDEX('Catálogo PCB'!$B$3:$B$102,MATCH(B16,'Catálogo PCB'!$A$3:$A$102,0))&"","")) | E16: TQT-R2-V30-0026 | F16: =IF(E16="","",IFERROR(INDEX('Catálogo PCB'!$G$3:$G$102,MATCH(E16,'Catálogo PCB'!$F$3:$F$102,0))&"","")) | N16: 2026-W15
A17: 0027 | B17: =IF(A17="","","TQT-R1-V30-"&TEXT(VALUE(A17),"0000")) -> TQT-R1-V30-0027 | C17: =IF(B17="","",IFERROR(INDEX('Catálogo PCB'!$B$3:$B$102,MATCH(B17,'Catálogo PCB'!$A$3:$A$102,0))&"","")) | E17: TQT-R2-V30-0027 | F17: =IF(E17="","",IFERROR(INDEX('Catálogo PCB'!$G$3:$G$102,MATCH(E17,'Catálogo PCB'!$F$3:$F$102,0))&"","")) | N17: 2026-W16
A18: 0028 | B18: =IF(A18="","","TQT-R1-V30-"&TEXT(VALUE(A18),"0000")) -> TQT-R1-V30-0028 | C18: =IF(B18="","",IFERROR(INDEX('Catálogo PCB'!$B$3:$B$102,MATCH(B18,'Catálogo PCB'!$A$3:$A$102,0))&"","")) | E18: TQT-R2-V30-0028 | F18: =IF(E18="","",IFERROR(INDEX('Catálogo PCB'!$G$3:$G$102,MATCH(E18,'Catálogo PCB'!$F$3:$F$102,0))&"","")) | N18: 2026-W17
A19: 0029 | B19: =IF(A19="","","TQT-R1-V30-"&TEXT(VALUE(A19),"0000")) -> TQT-R1-V30-0029 | C19: =IF(B19="","",IFERROR(INDEX('Catálogo PCB'!$B$3:$B$102,MATCH(B19,'Catálogo PCB'!$A$3:$A$102,0))&"","")) | E19: TQT-R2-V30-0029 | F19: =IF(E19="","",IFERROR(INDEX('Catálogo PCB'!$G$3:$G$102,MATCH(E19,'Catálogo PCB'!$F$3:$F$102,0))&"","")) | N19: 2026-W18
... A101: 0130 | B101: =IF(A101="","","TQT-R1-V30-"&TEXT(VALUE(A101),"0000")) -> TQT-R1-V30-0130 | C101: =IF(B101="","",IFERROR(INDEX('Catálogo PCB'!$B$3:$B$102,MATCH(B101,'Catálogo PCB'!$A$3:$A$102,0))&"","")) | E101: TQT-R2-V30-0116 | F101: =IF(E101="","",IFERROR(INDEX('Catálogo PCB'!$G$3:$G$102,MATCH(E101,'Catálogo PCB'!$F$3:$F$102,0))&"","")) | N101: 2027-W47
N102: 2027-W48
N103: 2027-W49
N104: 2027-W50
N105: 2027-W51
N106: 2027-W52
N107: 2027-W53

Sheet Pruebas
A1: ID Tarjeta | B1: Soldadura | C1: Programación | D1: Prueba PCB | E1: Integración | F1: Prueba Final | G1: Estado | J1: ACTUALIZACIÓN MASIVA DE PRUEBAS
A2: =IF(Producción!A2="","",Producción!A2) -> 0011 | B2: {=IF($A2="","",IFERROR(LOOKUP(2,1/(($K$3:$K$200="Soldadura")*((($M$3:$M$200=$A2)+($N$3:$N$200=$A2)+($O$3:$O$200=$A2)+($P$3:$P$200=$A2)+($Q$3:$Q$200=$A2)+($R$3:$R$200=$A2)+($S$3:$S$200=$A2)+($T$3:$T$200=$A2)+($U$3:$U$200=$A2)+($V$3:$V$200=$A2)+($W$3:$W$200=$A2)+($X$3:$X$200=$A2)+($Y$3:$Y$200=$A2)+($Z$3:$Z$200=$A2)+($AA$3:$AA$200=$A2))>0)),$L$3:$L$200),"PENDIENTE"))} -> PENDIENTE | C2: {=IF($A2="","",IFERROR(LOOKUP(2,1/(($K$3:$K$200="Programación")*((($M$3:$M$200=$A2)+($N$3:$N$200=$A2)+($O$3:$O$200=$A2)+($P$3:$P$200=$A2)+($Q$3:$Q$200=$A2)+($R$3:$R$200=$A2)+($S$3:$S$200=$A2)+($T$3:$T$200=$A2)+($U$3:$U$200=$A2)+($V$3:$V$200=$A2)+($W$3:$W$200=$A2)+($X$3:$X$200=$A2)+($Y$3:$Y$200=$A2)+($Z$3:$Z$200=$A2)+($AA$3:$AA$200=$A2))>0)),$L$3:$L$200),"PENDIENTE"))} -> PENDIENTE | D2: {=IF($A2="","",IFERROR(LOOKUP(2,1/(($K$3:$K$200="Prueba PCB")*((($M$3:$M$200=$A2)+($N$3:$N$200=$A2)+($O$3:$O$200=$A2)+($P$3:$P$200=$A2)+($Q$3:$Q$200=$A2)+($R$3:$R$200=$A2)+($S$3:$S$200=$A2)+($T$3:$T$200=$A2)+($U$3:$U$200=$A2)+($V$3:$V$200=$A2)+($W$3:$W$200=$A2)+($X$3:$X$200=$A2)+($Y$3:$Y$200=$A2)+($Z$3:$Z$200=$A2)+($AA$3:$AA$200=$A2))>0)),$L$3:$L$200),"PENDIENTE"))} -> PENDIENTE | E2: {=IF($A2="","",IFERROR(LOOKUP(2,1/(($K$3:$K$200="Integración")*((($M$3:$M$200=$A2)+($N$3:$N$200=$A2)+($O$3:$O$200=$A2)+($P$3:$P$200=$A2)+($Q$3:$Q$200=$A2)+($R$3:$R$200=$A2)+($S$3:$S$200=$A2)+($T$3:$T$200=$A2)+($U$3:$U$200=$A2)+($V$3:$V$200=$A2)+($W$3:$W$200=$A2)+($X$3:$X$200=$A2)+($Y$3:$Y$200=$A2)+($Z$3:$Z$200=$A2)+($AA$3:$AA$200=$A2))>0)),$L$3:$L$200),"PENDIENTE"))} -> PENDIENTE | F2: {=IF($A2="","",IFERROR(LOOKUP(2,1/(($K$3:$K$200="Prueba Final")*((($M$3:$M$200=$A2)+($N$3:$N$200=$A2)+($O$3:$O$200=$A2)+($P$3:$P$200=$A2)+($Q$3:$Q$200=$A2)+($R$3:$R$200=$A2)+($S$3:$S$200=$A2)+($T$3:$T$200=$A2)+($U$3:$U$200=$A2)+($V$3:$V$200=$A2)+($W$3:$W$200=$A2)+($X$3:$X$200=$A2)+($Y$3:$Y$200=$A2)+($Z$3:$Z$200=$A2)+($AA$3:$AA$200=$A2))>0)),$L$3:$L$200),"PENDIENTE"))} -> PENDIENTE | G2: =IF($A2="","",IF(COUNTIF(B2:F2,"FALLA")>0,"DETENIDO",IF(COUNTIF(B2:F2,"RETRABAJO")>0,"RETRABAJO",IF(COUNTIF(B2:F2,"OK")+COUNTIF(B2:F2,"NO APLICA")=5,"LIBERADO",IF(COUNTIF(B2:F2,"PENDIENTE")=5,"PENDIENTE","EN PROCESO"))))) -> PENDIENTE | J2: Fecha | K2: Proceso | L2: Estatus | M2: ID 1 | N2: ID 2 | O2: ID 3 | P2: ID 4 | Q2: ID 5 | R2: ID 6 | S2: ID 7 | T2: ID 8 | U2: ID 9 | V2: ID 10 | W2: ID 11 | X2: ID 12 | Y2: ID 13 | Z2: ID 14 | AA2: ID 15
A3: =IF(Producción!A3="","",Producción!A3) -> 0012 | B3: {=IF($A3="","",IFERROR(LOOKUP(2,1/(($K$3:$K$200="Soldadura")*((($M$3:$M$200=$A3)+($N$3:$N$200=$A3)+($O$3:$O$200=$A3)+($P$3:$P$200=$A3)+($Q$3:$Q$200=$A3)+($R$3:$R$200=$A3)+($S$3:$S$200=$A3)+($T$3:$T$200=$A3)+($U$3:$U$200=$A3)+($V$3:$V$200=$A3)+($W$3:$W$200=$A3)+($X$3:$X$200=$A3)+($Y$3:$Y$200=$A3)+($Z$3:$Z$200=$A3)+($AA$3:$AA$200=$A3))>0)),$L$3:$L$200),"PENDIENTE"))} -> PENDIENTE | C3: {=IF($A3="","",IFERROR(LOOKUP(2,1/(($K$3:$K$200="Programación")*((($M$3:$M$200=$A3)+($N$3:$N$200=$A3)+($O$3:$O$200=$A3)+($P$3:$P$200=$A3)+($Q$3:$Q$200=$A3)+($R$3:$R$200=$A3)+($S$3:$S$200=$A3)+($T$3:$T$200=$A3)+($U$3:$U$200=$A3)+($V$3:$V$200=$A3)+($W$3:$W$200=$A3)+($X$3:$X$200=$A3)+($Y$3:$Y$200=$A3)+($Z$3:$Z$200=$A3)+($AA$3:$AA$200=$A3))>0)),$L$3:$L$200),"PENDIENTE"))} -> PENDIENTE | D3: {=IF($A3="","",IFERROR(LOOKUP(2,1/(($K$3:$K$200="Prueba PCB")*((($M$3:$M$200=$A3)+($N$3:$N$200=$A3)+($O$3:$O$200=$A3)+($P$3:$P$200=$A3)+($Q$3:$Q$200=$A3)+($R$3:$R$200=$A3)+($S$3:$S$200=$A3)+($T$3:$T$200=$A3)+($U$3:$U$200=$A3)+($V$3:$V$200=$A3)+($W$3:$W$200=$A3)+($X$3:$X$200=$A3)+($Y$3:$Y$200=$A3)+($Z$3:$Z$200=$A3)+($AA$3:$AA$200=$A3))>0)),$L$3:$L$200),"PENDIENTE"))} -> PENDIENTE | E3: {=IF($A3="","",IFERROR(LOOKUP(2,1/(($K$3:$K$200="Integración")*((($M$3:$M$200=$A3)+($N$3:$N$200=$A3)+($O$3:$O$200=$A3)+($P$3:$P$200=$A3)+($Q$3:$Q$200=$A3)+($R$3:$R$200=$A3)+($S$3:$S$200=$A3)+($T$3:$T$200=$A3)+($U$3:$U$200=$A3)+($V$3:$V$200=$A3)+($W$3:$W$200=$A3)+($X$3:$X$200=$A3)+($Y$3:$Y$200=$A3)+($Z$3:$Z$200=$A3)+($AA$3:$AA$200=$A3))>0)),$L$3:$L$200),"PENDIENTE"))} -> PENDIENTE | F3: {=IF($A3="","",IFERROR(LOOKUP(2,1/(($K$3:$K$200="Prueba Final")*((($M$3:$M$200=$A3)+($N$3:$N$200=$A3)+($O$3:$O$200=$A3)+($P$3:$P$200=$A3)+($Q$3:$Q$200=$A3)+($R$3:$R$200=$A3)+($S$3:$S$200=$A3)+($T$3:$T$200=$A3)+($U$3:$U$200=$A3)+($V$3:$V$200=$A3)+($W$3:$W$200=$A3)+($X$3:$X$200=$A3)+($Y$3:$Y$200=$A3)+($Z$3:$Z$200=$A3)+($AA$3:$AA$200=$A3))>0)),$L$3:$L$200),"PENDIENTE"))} -> PENDIENTE | G3: =IF($A3="","",IF(COUNTIF(B3:F3,"FALLA")>0,"DETENIDO",IF(COUNTIF(B3:F3,"RETRABAJO")>0,"RETRABAJO",IF(COUNTIF(B3:F3,"OK")+COUNTIF(B3:F3,"NO APLICA")=5,"LIBERADO",IF(COUNTIF(B3:F3,"PENDIENTE")=5,"PENDIENTE","EN PROCESO"))))) -> PENDIENTE
A4: =IF(Producción!A4="","",Producción!A4) -> 0013 | B4: {=IF($A4="","",IFERROR(LOOKUP(2,1/(($K$3:$K$200="Soldadura")*((($M$3:$M$200=$A4)+($N$3:$N$200=$A4)+($O$3:$O$200=$A4)+($P$3:$P$200=$A4)+($Q$3:$Q$200=$A4)+($R$3:$R$200=$A4)+($S$3:$S$200=$A4)+($T$3:$T$200=$A4)+($U$3:$U$200=$A4)+($V$3:$V$200=$A4)+($W$3:$W$200=$A4)+($X$3:$X$200=$A4)+($Y$3:$Y$200=$A4)+($Z$3:$Z$200=$A4)+($AA$3:$AA$200=$A4))>0)),$L$3:$L$200),"PENDIENTE"))} -> PENDIENTE | C4: {=IF($A4="","",IFERROR(LOOKUP(2,1/(($K$3:$K$200="Programación")*((($M$3:$M$200=$A4)+($N$3:$N$200=$A4)+($O$3:$O$200=$A4)+($P$3:$P$200=$A4)+($Q$3:$Q$200=$A4)+($R$3:$R$200=$A4)+($S$3:$S$200=$A4)+($T$3:$T$200=$A4)+($U$3:$U$200=$A4)+($V$3:$V$200=$A4)+($W$3:$W$200=$A4)+($X$3:$X$200=$A4)+($Y$3:$Y$200=$A4)+($Z$3:$Z$200=$A4)+($AA$3:$AA$200=$A4))>0)),$L$3:$L$200),"PENDIENTE"))} -> PENDIENTE | D4: {=IF($A4="","",IFERROR(LOOKUP(2,1/(($K$3:$K$200="Prueba PCB")*((($M$3:$M$200=$A4)+($N$3:$N$200=$A4)+($O$3:$O$200=$A4)+($P$3:$P$200=$A4)+($Q$3:$Q$200=$A4)+($R$3:$R$200=$A4)+($S$3:$S$200=$A4)+($T$3:$T$200=$A4)+($U$3:$U$200=$A4)+($V$3:$V$200=$A4)+($W$3:$W$200=$A4)+($X$3:$X$200=$A4)+($Y$3:$Y$200=$A4)+($Z$3:$Z$200=$A4)+($AA$3:$AA$200=$A4))>0)),$L$3:$L$200),"PENDIENTE"))} -> PENDIENTE | E4: {=IF($A4="","",IFERROR(LOOKUP(2,1/(($K$3:$K$200="Integración")*((($M$3:$M$200=$A4)+($N$3:$N$200=$A4)+($O$3:$O$200=$A4)+($P$3:$P$200=$A4)+($Q$3:$Q$200=$A4)+($R$3:$R$200=$A4)+($S$3:$S$200=$A4)+($T$3:$T$200=$A4)+($U$3:$U$200=$A4)+($V$3:$V$200=$A4)+($W$3:$W$200=$A4)+($X$3:$X$200=$A4)+($Y$3:$Y$200=$A4)+($Z$3:$Z$200=$A4)+($AA$3:$AA$200=$A4))>0)),$L$3:$L$200),"PENDIENTE"))} -> PENDIENTE | F4: {=IF($A4="","",IFERROR(LOOKUP(2,1/(($K$3:$K$200="Prueba Final")*((($M$3:$M$200=$A4)+($N$3:$N$200=$A4)+($O$3:$O$200=$A4)+($P$3:$P$200=$A4)+($Q$3:$Q$200=$A4)+($R$3:$R$200=$A4)+($S$3:$S$200=$A4)+($T$3:$T$200=$A4)+($U$3:$U$200=$A4)+($V$3:$V$200=$A4)+($W$3:$W$200=$A4)+($X$3:$X$200=$A4)+($Y$3:$Y$200=$A4)+($Z$3:$Z$200=$A4)+($AA$3:$AA$200=$A4))>0)),$L$3:$L$200),"PENDIENTE"))} -> PENDIENTE | G4: =IF($A4="","",IF(COUNTIF(B4:F4,"FALLA")>0,"DETENIDO",IF(COUNTIF(B4:F4,"RETRABAJO")>0,"RETRABAJO",IF(COUNTIF(B4:F4,"OK")+COUNTIF(B4:F4,"NO APLICA")=5,"LIBERADO",IF(COUNTIF(B4:F4,"PENDIENTE")=5,"PENDIENTE","EN PROCESO"))))) -> PENDIENTE
A5: =IF(Producción!A5="","",Producción!A5) -> 0014 | B5: {=IF($A5="","",IFERROR(LOOKUP(2,1/(($K$3:$K$200="Soldadura")*((($M$3:$M$200=$A5)+($N$3:$N$200=$A5)+($O$3:$O$200=$A5)+($P$3:$P$200=$A5)+($Q$3:$Q$200=$A5)+($R$3:$R$200=$A5)+($S$3:$S$200=$A5)+($T$3:$T$200=$A5)+($U$3:$U$200=$A5)+($V$3:$V$200=$A5)+($W$3:$W$200=$A5)+($X$3:$X$200=$A5)+($Y$3:$Y$200=$A5)+($Z$3:$Z$200=$A5)+($AA$3:$AA$200=$A5))>0)),$L$3:$L$200),"PENDIENTE"))} -> PENDIENTE | C5: {=IF($A5="","",IFERROR(LOOKUP(2,1/(($K$3:$K$200="Programación")*((($M$3:$M$200=$A5)+($N$3:$N$200=$A5)+($O$3:$O$200=$A5)+($P$3:$P$200=$A5)+($Q$3:$Q$200=$A5)+($R$3:$R$200=$A5)+($S$3:$S$200=$A5)+($T$3:$T$200=$A5)+($U$3:$U$200=$A5)+($V$3:$V$200=$A5)+($W$3:$W$200=$A5)+($X$3:$X$200=$A5)+($Y$3:$Y$200=$A5)+($Z$3:$Z$200=$A5)+($AA$3:$AA$200=$A5))>0)),$L$3:$L$200),"PENDIENTE"))} -> PENDIENTE | D5: {=IF($A5="","",IFERROR(LOOKUP(2,1/(($K$3:$K$200="Prueba PCB")*((($M$3:$M$200=$A5)+($N$3:$N$200=$A5)+($O$3:$O$200=$A5)+($P$3:$P$200=$A5)+($Q$3:$Q$200=$A5)+($R$3:$R$200=$A5)+($S$3:$S$200=$A5)+($T$3:$T$200=$A5)+($U$3:$U$200=$A5)+($V$3:$V$200=$A5)+($W$3:$W$200=$A5)+($X$3:$X$200=$A5)+($Y$3:$Y$200=$A5)+($Z$3:$Z$200=$A5)+($AA$3:$AA$200=$A5))>0)),$L$3:$L$200),"PENDIENTE"))} -> PENDIENTE | E5: {=IF($A5="","",IFERROR(LOOKUP(2,1/(($K$3:$K$200="Integración")*((($M$3:$M$200=$A5)+($N$3:$N$200=$A5)+($O$3:$O$200=$A5)+($P$3:$P$200=$A5)+($Q$3:$Q$200=$A5)+($R$3:$R$200=$A5)+($S$3:$S$200=$A5)+($T$3:$T$200=$A5)+($U$3:$U$200=$A5)+($V$3:$V$200=$A5)+($W$3:$W$200=$A5)+($X$3:$X$200=$A5)+($Y$3:$Y$200=$A5)+($Z$3:$Z$200=$A5)+($AA$3:$AA$200=$A5))>0)),$L$3:$L$200),"PENDIENTE"))} -> PENDIENTE | F5: {=IF($A5="","",IFERROR(LOOKUP(2,1/(($K$3:$K$200="Prueba Final")*((($M$3:$M$200=$A5)+($N$3:$N$200=$A5)+($O$3:$O$200=$A5)+($P$3:$P$200=$A5)+($Q$3:$Q$200=$A5)+($R$3:$R$200=$A5)+($S$3:$S$200=$A5)+($T$3:$T$200=$A5)+($U$3:$U$200=$A5)+($V$3:$V$200=$A5)+($W$3:$W$200=$A5)+($X$3:$X$200=$A5)+($Y$3:$Y$200=$A5)+($Z$3:$Z$200=$A5)+($AA$3:$AA$200=$A5))>0)),$L$3:$L$200),"PENDIENTE"))} -> PENDIENTE | G5: =IF($A5="","",IF(COUNTIF(B5:F5,"FALLA")>0,"DETENIDO",IF(COUNTIF(B5:F5,"RETRABAJO")>0,"RETRABAJO",IF(COUNTIF(B5:F5,"OK")+COUNTIF(B5:F5,"NO APLICA")=5,"LIBERADO",IF(COUNTIF(B5:F5,"PENDIENTE")=5,"PENDIENTE","EN PROCESO"))))) -> PENDIENTE
A6: =IF(Producción!A6="","",Producción!A6) -> 0015 | B6: {=IF($A6="","",IFERROR(LOOKUP(2,1/(($K$3:$K$200="Soldadura")*((($M$3:$M$200=$A6)+($N$3:$N$200=$A6)+($O$3:$O$200=$A6)+($P$3:$P$200=$A6)+($Q$3:$Q$200=$A6)+($R$3:$R$200=$A6)+($S$3:$S$200=$A6)+($T$3:$T$200=$A6)+($U$3:$U$200=$A6)+($V$3:$V$200=$A6)+($W$3:$W$200=$A6)+($X$3:$X$200=$A6)+($Y$3:$Y$200=$A6)+($Z$3:$Z$200=$A6)+($AA$3:$AA$200=$A6))>0)),$L$3:$L$200),"PENDIENTE"))} -> PENDIENTE | C6: {=IF($A6="","",IFERROR(LOOKUP(2,1/(($K$3:$K$200="Programación")*((($M$3:$M$200=$A6)+($N$3:$N$200=$A6)+($O$3:$O$200=$A6)+($P$3:$P$200=$A6)+($Q$3:$Q$200=$A6)+($R$3:$R$200=$A6)+($S$3:$S$200=$A6)+($T$3:$T$200=$A6)+($U$3:$U$200=$A6)+($V$3:$V$200=$A6)+($W$3:$W$200=$A6)+($X$3:$X$200=$A6)+($Y$3:$Y$200=$A6)+($Z$3:$Z$200=$A6)+($AA$3:$AA$200=$A6))>0)),$L$3:$L$200),"PENDIENTE"))} -> PENDIENTE | D6: {=IF($A6="","",IFERROR(LOOKUP(2,1/(($K$3:$K$200="Prueba PCB")*((($M$3:$M$200=$A6)+($N$3:$N$200=$A6)+($O$3:$O$200=$A6)+($P$3:$P$200=$A6)+($Q$3:$Q$200=$A6)+($R$3:$R$200=$A6)+($S$3:$S$200=$A6)+($T$3:$T$200=$A6)+($U$3:$U$200=$A6)+($V$3:$V$200=$A6)+($W$3:$W$200=$A6)+($X$3:$X$200=$A6)+($Y$3:$Y$200=$A6)+($Z$3:$Z$200=$A6)+($AA$3:$AA$200=$A6))>0)),$L$3:$L$200),"PENDIENTE"))} -> PENDIENTE | E6: {=IF($A6="","",IFERROR(LOOKUP(2,1/(($K$3:$K$200="Integración")*((($M$3:$M$200=$A6)+($N$3:$N$200=$A6)+($O$3:$O$200=$A6)+($P$3:$P$200=$A6)+($Q$3:$Q$200=$A6)+($R$3:$R$200=$A6)+($S$3:$S$200=$A6)+($T$3:$T$200=$A6)+($U$3:$U$200=$A6)+($V$3:$V$200=$A6)+($W$3:$W$200=$A6)+($X$3:$X$200=$A6)+($Y$3:$Y$200=$A6)+($Z$3:$Z$200=$A6)+($AA$3:$AA$200=$A6))>0)),$L$3:$L$200),"PENDIENTE"))} -> PENDIENTE | F6: {=IF($A6="","",IFERROR(LOOKUP(2,1/(($K$3:$K$200="Prueba Final")*((($M$3:$M$200=$A6)+($N$3:$N$200=$A6)+($O$3:$O$200=$A6)+($P$3:$P$200=$A6)+($Q$3:$Q$200=$A6)+($R$3:$R$200=$A6)+($S$3:$S$200=$A6)+($T$3:$T$200=$A6)+($U$3:$U$200=$A6)+($V$3:$V$200=$A6)+($W$3:$W$200=$A6)+($X$3:$X$200=$A6)+($Y$3:$Y$200=$A6)+($Z$3:$Z$200=$A6)+($AA$3:$AA$200=$A6))>0)),$L$3:$L$200),"PENDIENTE"))} -> PENDIENTE | G6: =IF($A6="","",IF(COUNTIF(B6:F6,"FALLA")>0,"DETENIDO",IF(COUNTIF(B6:F6,"RETRABAJO")>0,"RETRABAJO",IF(COUNTIF(B6:F6,"OK")+COUNTIF(B6:F6,"NO APLICA")=5,"LIBERADO",IF(COUNTIF(B6:F6,"PENDIENTE")=5,"PENDIENTE","EN PROCESO"))))) -> PENDIENTE
A7: =IF(Producción!A7="","",Producción!A7) -> 0016 | B7: {=IF($A7="","",IFERROR(LOOKUP(2,1/(($K$3:$K$200="Soldadura")*((($M$3:$M$200=$A7)+($N$3:$N$200=$A7)+($O$3:$O$200=$A7)+($P$3:$P$200=$A7)+($Q$3:$Q$200=$A7)+($R$3:$R$200=$A7)+($S$3:$S$200=$A7)+($T$3:$T$200=$A7)+($U$3:$U$200=$A7)+($V$3:$V$200=$A7)+($W$3:$W$200=$A7)+($X$3:$X$200=$A7)+($Y$3:$Y$200=$A7)+($Z$3:$Z$200=$A7)+($AA$3:$AA$200=$A7))>0)),$L$3:$L$200),"PENDIENTE"))} -> PENDIENTE | C7: {=IF($A7="","",IFERROR(LOOKUP(2,1/(($K$3:$K$200="Programación")*((($M$3:$M$200=$A7)+($N$3:$N$200=$A7)+($O$3:$O$200=$A7)+($P$3:$P$200=$A7)+($Q$3:$Q$200=$A7)+($R$3:$R$200=$A7)+($S$3:$S$200=$A7)+($T$3:$T$200=$A7)+($U$3:$U$200=$A7)+($V$3:$V$200=$A7)+($W$3:$W$200=$A7)+($X$3:$X$200=$A7)+($Y$3:$Y$200=$A7)+($Z$3:$Z$200=$A7)+($AA$3:$AA$200=$A7))>0)),$L$3:$L$200),"PENDIENTE"))} -> PENDIENTE | D7: {=IF($A7="","",IFERROR(LOOKUP(2,1/(($K$3:$K$200="Prueba PCB")*((($M$3:$M$200=$A7)+($N$3:$N$200=$A7)+($O$3:$O$200=$A7)+($P$3:$P$200=$A7)+($Q$3:$Q$200=$A7)+($R$3:$R$200=$A7)+($S$3:$S$200=$A7)+($T$3:$T$200=$A7)+($U$3:$U$200=$A7)+($V$3:$V$200=$A7)+($W$3:$W$200=$A7)+($X$3:$X$200=$A7)+($Y$3:$Y$200=$A7)+($Z$3:$Z$200=$A7)+($AA$3:$AA$200=$A7))>0)),$L$3:$L$200),"PENDIENTE"))} -> PENDIENTE | E7: {=IF($A7="","",IFERROR(LOOKUP(2,1/(($K$3:$K$200="Integración")*((($M$3:$M$200=$A7)+($N$3:$N$200=$A7)+($O$3:$O$200=$A7)+($P$3:$P$200=$A7)+($Q$3:$Q$200=$A7)+($R$3:$R$200=$A7)+($S$3:$S$200=$A7)+($T$3:$T$200=$A7)+($U$3:$U$200=$A7)+($V$3:$V$200=$A7)+($W$3:$W$200=$A7)+($X$3:$X$200=$A7)+($Y$3:$Y$200=$A7)+($Z$3:$Z$200=$A7)+($AA$3:$AA$200=$A7))>0)),$L$3:$L$200),"PENDIENTE"))} -> PENDIENTE | F7: {=IF($A7="","",IFERROR(LOOKUP(2,1/(($K$3:$K$200="Prueba Final")*((($M$3:$M$200=$A7)+($N$3:$N$200=$A7)+($O$3:$O$200=$A7)+($P$3:$P$200=$A7)+($Q$3:$Q$200=$A7)+($R$3:$R$200=$A7)+($S$3:$S$200=$A7)+($T$3:$T$200=$A7)+($U$3:$U$200=$A7)+($V$3:$V$200=$A7)+($W$3:$W$200=$A7)+($X$3:$X$200=$A7)+($Y$3:$Y$200=$A7)+($Z$3:$Z$200=$A7)+($AA$3:$AA$200=$A7))>0)),$L$3:$L$200),"PENDIENTE"))} -> PENDIENTE | G7: =IF($A7="","",IF(COUNTIF(B7:F7,"FALLA")>0,"DETENIDO",IF(COUNTIF(B7:F7,"RETRABAJO")>0,"RETRABAJO",IF(COUNTIF(B7:F7,"OK")+COUNTIF(B7:F7,"NO APLICA")=5,"LIBERADO",IF(COUNTIF(B7:F7,"PENDIENTE")=5,"PENDIENTE","EN PROCESO"))))) -> PENDIENTE
A8: =IF(Producción!A8="","",Producción!A8) -> 0017 | B8: {=IF($A8="","",IFERROR(LOOKUP(2,1/(($K$3:$K$200="Soldadura")*((($M$3:$M$200=$A8)+($N$3:$N$200=$A8)+($O$3:$O$200=$A8)+($P$3:$P$200=$A8)+($Q$3:$Q$200=$A8)+($R$3:$R$200=$A8)+($S$3:$S$200=$A8)+($T$3:$T$200=$A8)+($U$3:$U$200=$A8)+($V$3:$V$200=$A8)+($W$3:$W$200=$A8)+($X$3:$X$200=$A8)+($Y$3:$Y$200=$A8)+($Z$3:$Z$200=$A8)+($AA$3:$AA$200=$A8))>0)),$L$3:$L$200),"PENDIENTE"))} -> PENDIENTE | C8: {=IF($A8="","",IFERROR(LOOKUP(2,1/(($K$3:$K$200="Programación")*((($M$3:$M$200=$A8)+($N$3:$N$200=$A8)+($O$3:$O$200=$A8)+($P$3:$P$200=$A8)+($Q$3:$Q$200=$A8)+($R$3:$R$200=$A8)+($S$3:$S$200=$A8)+($T$3:$T$200=$A8)+($U$3:$U$200=$A8)+($V$3:$V$200=$A8)+($W$3:$W$200=$A8)+($X$3:$X$200=$A8)+($Y$3:$Y$200=$A8)+($Z$3:$Z$200=$A8)+($AA$3:$AA$200=$A8))>0)),$L$3:$L$200),"PENDIENTE"))} -> PENDIENTE | D8: {=IF($A8="","",IFERROR(LOOKUP(2,1/(($K$3:$K$200="Prueba PCB")*((($M$3:$M$200=$A8)+($N$3:$N$200=$A8)+($O$3:$O$200=$A8)+($P$3:$P$200=$A8)+($Q$3:$Q$200=$A8)+($R$3:$R$200=$A8)+($S$3:$S$200=$A8)+($T$3:$T$200=$A8)+($U$3:$U$200=$A8)+($V$3:$V$200=$A8)+($W$3:$W$200=$A8)+($X$3:$X$200=$A8)+($Y$3:$Y$200=$A8)+($Z$3:$Z$200=$A8)+($AA$3:$AA$200=$A8))>0)),$L$3:$L$200),"PENDIENTE"))} -> PENDIENTE | E8: {=IF($A8="","",IFERROR(LOOKUP(2,1/(($K$3:$K$200="Integración")*((($M$3:$M$200=$A8)+($N$3:$N$200=$A8)+($O$3:$O$200=$A8)+($P$3:$P$200=$A8)+($Q$3:$Q$200=$A8)+($R$3:$R$200=$A8)+($S$3:$S$200=$A8)+($T$3:$T$200=$A8)+($U$3:$U$200=$A8)+($V$3:$V$200=$A8)+($W$3:$W$200=$A8)+($X$3:$X$200=$A8)+($Y$3:$Y$200=$A8)+($Z$3:$Z$200=$A8)+($AA$3:$AA$200=$A8))>0)),$L$3:$L$200),"PENDIENTE"))} -> PENDIENTE | F8: {=IF($A8="","",IFERROR(LOOKUP(2,1/(($K$3:$K$200="Prueba Final")*((($M$3:$M$200=$A8)+($N$3:$N$200=$A8)+($O$3:$O$200=$A8)+($P$3:$P$200=$A8)+($Q$3:$Q$200=$A8)+($R$3:$R$200=$A8)+($S$3:$S$200=$A8)+($T$3:$T$200=$A8)+($U$3:$U$200=$A8)+($V$3:$V$200=$A8)+($W$3:$W$200=$A8)+($X$3:$X$200=$A8)+($Y$3:$Y$200=$A8)+($Z$3:$Z$200=$A8)+($AA$3:$AA$200=$A8))>0)),$L$3:$L$200),"PENDIENTE"))} -> PENDIENTE | G8: =IF($A8="","",IF(COUNTIF(B8:F8,"FALLA")>0,"DETENIDO",IF(COUNTIF(B8:F8,"RETRABAJO")>0,"RETRABAJO",IF(COUNTIF(B8:F8,"OK")+COUNTIF(B8:F8,"NO APLICA")=5,"LIBERADO",IF(COUNTIF(B8:F8,"PENDIENTE")=5,"PENDIENTE","EN PROCESO"))))) -> PENDIENTE
A9: =IF(Producción!A9="","",Producción!A9) -> 0019 | B9: {=IF($A9="","",IFERROR(LOOKUP(2,1/(($K$3:$K$200="Soldadura")*((($M$3:$M$200=$A9)+($N$3:$N$200=$A9)+($O$3:$O$200=$A9)+($P$3:$P$200=$A9)+($Q$3:$Q$200=$A9)+($R$3:$R$200=$A9)+($S$3:$S$200=$A9)+($T$3:$T$200=$A9)+($U$3:$U$200=$A9)+($V$3:$V$200=$A9)+($W$3:$W$200=$A9)+($X$3:$X$200=$A9)+($Y$3:$Y$200=$A9)+($Z$3:$Z$200=$A9)+($AA$3:$AA$200=$A9))>0)),$L$3:$L$200),"PENDIENTE"))} -> PENDIENTE | C9: {=IF($A9="","",IFERROR(LOOKUP(2,1/(($K$3:$K$200="Programación")*((($M$3:$M$200=$A9)+($N$3:$N$200=$A9)+($O$3:$O$200=$A9)+($P$3:$P$200=$A9)+($Q$3:$Q$200=$A9)+($R$3:$R$200=$A9)+($S$3:$S$200=$A9)+($T$3:$T$200=$A9)+($U$3:$U$200=$A9)+($V$3:$V$200=$A9)+($W$3:$W$200=$A9)+($X$3:$X$200=$A9)+($Y$3:$Y$200=$A9)+($Z$3:$Z$200=$A9)+($AA$3:$AA$200=$A9))>0)),$L$3:$L$200),"PENDIENTE"))} -> PENDIENTE | D9: {=IF($A9="","",IFERROR(LOOKUP(2,1/(($K$3:$K$200="Prueba PCB")*((($M$3:$M$200=$A9)+($N$3:$N$200=$A9)+($O$3:$O$200=$A9)+($P$3:$P$200=$A9)+($Q$3:$Q$200=$A9)+($R$3:$R$200=$A9)+($S$3:$S$200=$A9)+($T$3:$T$200=$A9)+($U$3:$U$200=$A9)+($V$3:$V$200=$A9)+($W$3:$W$200=$A9)+($X$3:$X$200=$A9)+($Y$3:$Y$200=$A9)+($Z$3:$Z$200=$A9)+($AA$3:$AA$200=$A9))>0)),$L$3:$L$200),"PENDIENTE"))} -> PENDIENTE | E9: {=IF($A9="","",IFERROR(LOOKUP(2,1/(($K$3:$K$200="Integración")*((($M$3:$M$200=$A9)+($N$3:$N$200=$A9)+($O$3:$O$200=$A9)+($P$3:$P$200=$A9)+($Q$3:$Q$200=$A9)+($R$3:$R$200=$A9)+($S$3:$S$200=$A9)+($T$3:$T$200=$A9)+($U$3:$U$200=$A9)+($V$3:$V$200=$A9)+($W$3:$W$200=$A9)+($X$3:$X$200=$A9)+($Y$3:$Y$200=$A9)+($Z$3:$Z$200=$A9)+($AA$3:$AA$200=$A9))>0)),$L$3:$L$200),"PENDIENTE"))} -> PENDIENTE | F9: {=IF($A9="","",IFERROR(LOOKUP(2,1/(($K$3:$K$200="Prueba Final")*((($M$3:$M$200=$A9)+($N$3:$N$200=$A9)+($O$3:$O$200=$A9)+($P$3:$P$200=$A9)+($Q$3:$Q$200=$A9)+($R$3:$R$200=$A9)+($S$3:$S$200=$A9)+($T$3:$T$200=$A9)+($U$3:$U$200=$A9)+($V$3:$V$200=$A9)+($W$3:$W$200=$A9)+($X$3:$X$200=$A9)+($Y$3:$Y$200=$A9)+($Z$3:$Z$200=$A9)+($AA$3:$AA$200=$A9))>0)),$L$3:$L$200),"PENDIENTE"))} -> PENDIENTE | G9: =IF($A9="","",IF(COUNTIF(B9:F9,"FALLA")>0,"DETENIDO",IF(COUNTIF(B9:F9,"RETRABAJO")>0,"RETRABAJO",IF(COUNTIF(B9:F9,"OK")+COUNTIF(B9:F9,"NO APLICA")=5,"LIBERADO",IF(COUNTIF(B9:F9,"PENDIENTE")=5,"PENDIENTE","EN PROCESO"))))) -> PENDIENTE
A10: =IF(Producción!A10="","",Producción!A10) -> 0020 | B10: {=IF($A10="","",IFERROR(LOOKUP(2,1/(($K$3:$K$200="Soldadura")*((($M$3:$M$200=$A10)+($N$3:$N$200=$A10)+($O$3:$O$200=$A10)+($P$3:$P$200=$A10)+($Q$3:$Q$200=$A10)+($R$3:$R$200=$A10)+($S$3:$S$200=$A10)+($T$3:$T$200=$A10)+($U$3:$U$200=$A10)+($V$3:$V$200=$A10)+($W$3:$W$200=$A10)+($X$3:$X$200=$A10)+($Y$3:$Y$200=$A10)+($Z$3:$Z$200=$A10)+($AA$3:$AA$200=$A10))>0)),$L$3:$L$200),"PENDIENTE"))} -> PENDIENTE | C10: {=IF($A10="","",IFERROR(LOOKUP(2,1/(($K$3:$K$200="Programación")*((($M$3:$M$200=$A10)+($N$3:$N$200=$A10)+($O$3:$O$200=$A10)+($P$3:$P$200=$A10)+($Q$3:$Q$200=$A10)+($R$3:$R$200=$A10)+($S$3:$S$200=$A10)+($T$3:$T$200=$A10)+($U$3:$U$200=$A10)+($V$3:$V$200=$A10)+($W$3:$W$200=$A10)+($X$3:$X$200=$A10)+($Y$3:$Y$200=$A10)+($Z$3:$Z$200=$A10)+($AA$3:$AA$200=$A10))>0)),$L$3:$L$200),"PENDIENTE"))} -> PENDIENTE | D10: {=IF($A10="","",IFERROR(LOOKUP(2,1/(($K$3:$K$200="Prueba PCB")*((($M$3:$M$200=$A10)+($N$3:$N$200=$A10)+($O$3:$O$200=$A10)+($P$3:$P$200=$A10)+($Q$3:$Q$200=$A10)+($R$3:$R$200=$A10)+($S$3:$S$200=$A10)+($T$3:$T$200=$A10)+($U$3:$U$200=$A10)+($V$3:$V$200=$A10)+($W$3:$W$200=$A10)+($X$3:$X$200=$A10)+($Y$3:$Y$200=$A10)+($Z$3:$Z$200=$A10)+($AA$3:$AA$200=$A10))>0)),$L$3:$L$200),"PENDIENTE"))} -> PENDIENTE | E10: {=IF($A10="","",IFERROR(LOOKUP(2,1/(($K$3:$K$200="Integración")*((($M$3:$M$200=$A10)+($N$3:$N$200=$A10)+($O$3:$O$200=$A10)+($P$3:$P$200=$A10)+($Q$3:$Q$200=$A10)+($R$3:$R$200=$A10)+($S$3:$S$200=$A10)+($T$3:$T$200=$A10)+($U$3:$U$200=$A10)+($V$3:$V$200=$A10)+($W$3:$W$200=$A10)+($X$3:$X$200=$A10)+($Y$3:$Y$200=$A10)+($Z$3:$Z$200=$A10)+($AA$3:$AA$200=$A10))>0)),$L$3:$L$200),"PENDIENTE"))} -> PENDIENTE | F10: {=IF($A10="","",IFERROR(LOOKUP(2,1/(($K$3:$K$200="Prueba Final")*((($M$3:$M$200=$A10)+($N$3:$N$200=$A10)+($O$3:$O$200=$A10)+($P$3:$P$200=$A10)+($Q$3:$Q$200=$A10)+($R$3:$R$200=$A10)+($S$3:$S$200=$A10)+($T$3:$T$200=$A10)+($U$3:$U$200=$A10)+($V$3:$V$200=$A10)+($W$3:$W$200=$A10)+($X$3:$X$200=$A10)+($Y$3:$Y$200=$A10)+($Z$3:$Z$200=$A10)+($AA$3:$AA$200=$A10))>0)),$L$3:$L$200),"PENDIENTE"))} -> PENDIENTE | G10: =IF($A10="","",IF(COUNTIF(B10:F10,"FALLA")>0,"DETENIDO",IF(COUNTIF(B10:F10,"RETRABAJO")>0,"RETRABAJO",IF(COUNTIF(B10:F10,"OK")+COUNTIF(B10:F10,"NO APLICA")=5,"LIBERADO",IF(COUNTIF(B10:F10,"PENDIENTE")=5,"PENDIENTE","EN PROCESO"))))) -> PENDIENTE
A11: =IF(Producción!A11="","",Producción!A11) -> 0021 | B11: {=IF($A11="","",IFERROR(LOOKUP(2,1/(($K$3:$K$200="Soldadura")*((($M$3:$M$200=$A11)+($N$3:$N$200=$A11)+($O$3:$O$200=$A11)+($P$3:$P$200=$A11)+($Q$3:$Q$200=$A11)+($R$3:$R$200=$A11)+($S$3:$S$200=$A11)+($T$3:$T$200=$A11)+($U$3:$U$200=$A11)+($V$3:$V$200=$A11)+($W$3:$W$200=$A11)+($X$3:$X$200=$A11)+($Y$3:$Y$200=$A11)+($Z$3:$Z$200=$A11)+($AA$3:$AA$200=$A11))>0)),$L$3:$L$200),"PENDIENTE"))} -> PENDIENTE | C11: {=IF($A11="","",IFERROR(LOOKUP(2,1/(($K$3:$K$200="Programación")*((($M$3:$M$200=$A11)+($N$3:$N$200=$A11)+($O$3:$O$200=$A11)+($P$3:$P$200=$A11)+($Q$3:$Q$200=$A11)+($R$3:$R$200=$A11)+($S$3:$S$200=$A11)+($T$3:$T$200=$A11)+($U$3:$U$200=$A11)+($V$3:$V$200=$A11)+($W$3:$W$200=$A11)+($X$3:$X$200=$A11)+($Y$3:$Y$200=$A11)+($Z$3:$Z$200=$A11)+($AA$3:$AA$200=$A11))>0)),$L$3:$L$200),"PENDIENTE"))} -> PENDIENTE | D11: {=IF($A11="","",IFERROR(LOOKUP(2,1/(($K$3:$K$200="Prueba PCB")*((($M$3:$M$200=$A11)+($N$3:$N$200=$A11)+($O$3:$O$200=$A11)+($P$3:$P$200=$A11)+($Q$3:$Q$200=$A11)+($R$3:$R$200=$A11)+($S$3:$S$200=$A11)+($T$3:$T$200=$A11)+($U$3:$U$200=$A11)+($V$3:$V$200=$A11)+($W$3:$W$200=$A11)+($X$3:$X$200=$A11)+($Y$3:$Y$200=$A11)+($Z$3:$Z$200=$A11)+($AA$3:$AA$200=$A11))>0)),$L$3:$L$200),"PENDIENTE"))} -> PENDIENTE | E11: {=IF($A11="","",IFERROR(LOOKUP(2,1/(($K$3:$K$200="Integración")*((($M$3:$M$200=$A11)+($N$3:$N$200=$A11)+($O$3:$O$200=$A11)+($P$3:$P$200=$A11)+($Q$3:$Q$200=$A11)+($R$3:$R$200=$A11)+($S$3:$S$200=$A11)+($T$3:$T$200=$A11)+($U$3:$U$200=$A11)+($V$3:$V$200=$A11)+($W$3:$W$200=$A11)+($X$3:$X$200=$A11)+($Y$3:$Y$200=$A11)+($Z$3:$Z$200=$A11)+($AA$3:$AA$200=$A11))>0)),$L$3:$L$200),"PENDIENTE"))} -> PENDIENTE | F11: {=IF($A11="","",IFERROR(LOOKUP(2,1/(($K$3:$K$200="Prueba Final")*((($M$3:$M$200=$A11)+($N$3:$N$200=$A11)+($O$3:$O$200=$A11)+($P$3:$P$200=$A11)+($Q$3:$Q$200=$A11)+($R$3:$R$200=$A11)+($S$3:$S$200=$A11)+($T$3:$T$200=$A11)+($U$3:$U$200=$A11)+($V$3:$V$200=$A11)+($W$3:$W$200=$A11)+($X$3:$X$200=$A11)+($Y$3:$Y$200=$A11)+($Z$3:$Z$200=$A11)+($AA$3:$AA$200=$A11))>0)),$L$3:$L$200),"PENDIENTE"))} -> PENDIENTE | G11: =IF($A11="","",IF(COUNTIF(B11:F11,"FALLA")>0,"DETENIDO",IF(COUNTIF(B11:F11,"RETRABAJO")>0,"RETRABAJO",IF(COUNTIF(B11:F11,"OK")+COUNTIF(B11:F11,"NO APLICA")=5,"LIBERADO",IF(COUNTIF(B11:F11,"PENDIENTE")=5,"PENDIENTE","EN PROCESO"))))) -> PENDIENTE
A12: =IF(Producción!A12="","",Producción!A12) -> 0022 | B12: {=IF($A12="","",IFERROR(LOOKUP(2,1/(($K$3:$K$200="Soldadura")*((($M$3:$M$200=$A12)+($N$3:$N$200=$A12)+($O$3:$O$200=$A12)+($P$3:$P$200=$A12)+($Q$3:$Q$200=$A12)+($R$3:$R$200=$A12)+($S$3:$S$200=$A12)+($T$3:$T$200=$A12)+($U$3:$U$200=$A12)+($V$3:$V$200=$A12)+($W$3:$W$200=$A12)+($X$3:$X$200=$A12)+($Y$3:$Y$200=$A12)+($Z$3:$Z$200=$A12)+($AA$3:$AA$200=$A12))>0)),$L$3:$L$200),"PENDIENTE"))} -> PENDIENTE | C12: {=IF($A12="","",IFERROR(LOOKUP(2,1/(($K$3:$K$200="Programación")*((($M$3:$M$200=$A12)+($N$3:$N$200=$A12)+($O$3:$O$200=$A12)+($P$3:$P$200=$A12)+($Q$3:$Q$200=$A12)+($R$3:$R$200=$A12)+($S$3:$S$200=$A12)+($T$3:$T$200=$A12)+($U$3:$U$200=$A12)+($V$3:$V$200=$A12)+($W$3:$W$200=$A12)+($X$3:$X$200=$A12)+($Y$3:$Y$200=$A12)+($Z$3:$Z$200=$A12)+($AA$3:$AA$200=$A12))>0)),$L$3:$L$200),"PENDIENTE"))} -> PENDIENTE | D12: {=IF($A12="","",IFERROR(LOOKUP(2,1/(($K$3:$K$200="Prueba PCB")*((($M$3:$M$200=$A12)+($N$3:$N$200=$A12)+($O$3:$O$200=$A12)+($P$3:$P$200=$A12)+($Q$3:$Q$200=$A12)+($R$3:$R$200=$A12)+($S$3:$S$200=$A12)+($T$3:$T$200=$A12)+($U$3:$U$200=$A12)+($V$3:$V$200=$A12)+($W$3:$W$200=$A12)+($X$3:$X$200=$A12)+($Y$3:$Y$200=$A12)+($Z$3:$Z$200=$A12)+($AA$3:$AA$200=$A12))>0)),$L$3:$L$200),"PENDIENTE"))} -> PENDIENTE | E12: {=IF($A12="","",IFERROR(LOOKUP(2,1/(($K$3:$K$200="Integración")*((($M$3:$M$200=$A12)+($N$3:$N$200=$A12)+($O$3:$O$200=$A12)+($P$3:$P$200=$A12)+($Q$3:$Q$200=$A12)+($R$3:$R$200=$A12)+($S$3:$S$200=$A12)+($T$3:$T$200=$A12)+($U$3:$U$200=$A12)+($V$3:$V$200=$A12)+($W$3:$W$200=$A12)+($X$3:$X$200=$A12)+($Y$3:$Y$200=$A12)+($Z$3:$Z$200=$A12)+($AA$3:$AA$200=$A12))>0)),$L$3:$L$200),"PENDIENTE"))} -> PENDIENTE | F12: {=IF($A12="","",IFERROR(LOOKUP(2,1/(($K$3:$K$200="Prueba Final")*((($M$3:$M$200=$A12)+($N$3:$N$200=$A12)+($O$3:$O$200=$A12)+($P$3:$P$200=$A12)+($Q$3:$Q$200=$A12)+($R$3:$R$200=$A12)+($S$3:$S$200=$A12)+($T$3:$T$200=$A12)+($U$3:$U$200=$A12)+($V$3:$V$200=$A12)+($W$3:$W$200=$A12)+($X$3:$X$200=$A12)+($Y$3:$Y$200=$A12)+($Z$3:$Z$200=$A12)+($AA$3:$AA$200=$A12))>0)),$L$3:$L$200),"PENDIENTE"))} -> PENDIENTE | G12: =IF($A12="","",IF(COUNTIF(B12:F12,"FALLA")>0,"DETENIDO",IF(COUNTIF(B12:F12,"RETRABAJO")>0,"RETRABAJO",IF(COUNTIF(B12:F12,"OK")+COUNTIF(B12:F12,"NO APLICA")=5,"LIBERADO",IF(COUNTIF(B12:F12,"PENDIENTE")=5,"PENDIENTE","EN PROCESO"))))) -> PENDIENTE
A13: =IF(Producción!A13="","",Producción!A13) -> 0023 | B13: {=IF($A13="","",IFERROR(LOOKUP(2,1/(($K$3:$K$200="Soldadura")*((($M$3:$M$200=$A13)+($N$3:$N$200=$A13)+($O$3:$O$200=$A13)+($P$3:$P$200=$A13)+($Q$3:$Q$200=$A13)+($R$3:$R$200=$A13)+($S$3:$S$200=$A13)+($T$3:$T$200=$A13)+($U$3:$U$200=$A13)+($V$3:$V$200=$A13)+($W$3:$W$200=$A13)+($X$3:$X$200=$A13)+($Y$3:$Y$200=$A13)+($Z$3:$Z$200=$A13)+($AA$3:$AA$200=$A13))>0)),$L$3:$L$200),"PENDIENTE"))} -> PENDIENTE | C13: {=IF($A13="","",IFERROR(LOOKUP(2,1/(($K$3:$K$200="Programación")*((($M$3:$M$200=$A13)+($N$3:$N$200=$A13)+($O$3:$O$200=$A13)+($P$3:$P$200=$A13)+($Q$3:$Q$200=$A13)+($R$3:$R$200=$A13)+($S$3:$S$200=$A13)+($T$3:$T$200=$A13)+($U$3:$U$200=$A13)+($V$3:$V$200=$A13)+($W$3:$W$200=$A13)+($X$3:$X$200=$A13)+($Y$3:$Y$200=$A13)+($Z$3:$Z$200=$A13)+($AA$3:$AA$200=$A13))>0)),$L$3:$L$200),"PENDIENTE"))} -> PENDIENTE | D13: {=IF($A13="","",IFERROR(LOOKUP(2,1/(($K$3:$K$200="Prueba PCB")*((($M$3:$M$200=$A13)+($N$3:$N$200=$A13)+($O$3:$O$200=$A13)+($P$3:$P$200=$A13)+($Q$3:$Q$200=$A13)+($R$3:$R$200=$A13)+($S$3:$S$200=$A13)+($T$3:$T$200=$A13)+($U$3:$U$200=$A13)+($V$3:$V$200=$A13)+($W$3:$W$200=$A13)+($X$3:$X$200=$A13)+($Y$3:$Y$200=$A13)+($Z$3:$Z$200=$A13)+($AA$3:$AA$200=$A13))>0)),$L$3:$L$200),"PENDIENTE"))} -> PENDIENTE | E13: {=IF($A13="","",IFERROR(LOOKUP(2,1/(($K$3:$K$200="Integración")*((($M$3:$M$200=$A13)+($N$3:$N$200=$A13)+($O$3:$O$200=$A13)+($P$3:$P$200=$A13)+($Q$3:$Q$200=$A13)+($R$3:$R$200=$A13)+($S$3:$S$200=$A13)+($T$3:$T$200=$A13)+($U$3:$U$200=$A13)+($V$3:$V$200=$A13)+($W$3:$W$200=$A13)+($X$3:$X$200=$A13)+($Y$3:$Y$200=$A13)+($Z$3:$Z$200=$A13)+($AA$3:$AA$200=$A13))>0)),$L$3:$L$200),"PENDIENTE"))} -> PENDIENTE | F13: {=IF($A13="","",IFERROR(LOOKUP(2,1/(($K$3:$K$200="Prueba Final")*((($M$3:$M$200=$A13)+($N$3:$N$200=$A13)+($O$3:$O$200=$A13)+($P$3:$P$200=$A13)+($Q$3:$Q$200=$A13)+($R$3:$R$200=$A13)+($S$3:$S$200=$A13)+($T$3:$T$200=$A13)+($U$3:$U$200=$A13)+($V$3:$V$200=$A13)+($W$3:$W$200=$A13)+($X$3:$X$200=$A13)+($Y$3:$Y$200=$A13)+($Z$3:$Z$200=$A13)+($AA$3:$AA$200=$A13))>0)),$L$3:$L$200),"PENDIENTE"))} -> PENDIENTE | G13: =IF($A13="","",IF(COUNTIF(B13:F13,"FALLA")>0,"DETENIDO",IF(COUNTIF(B13:F13,"RETRABAJO")>0,"RETRABAJO",IF(COUNTIF(B13:F13,"OK")+COUNTIF(B13:F13,"NO APLICA")=5,"LIBERADO",IF(COUNTIF(B13:F13,"PENDIENTE")=5,"PENDIENTE","EN PROCESO"))))) -> PENDIENTE
A14: =IF(Producción!A14="","",Producción!A14) -> 0024 | B14: {=IF($A14="","",IFERROR(LOOKUP(2,1/(($K$3:$K$200="Soldadura")*((($M$3:$M$200=$A14)+($N$3:$N$200=$A14)+($O$3:$O$200=$A14)+($P$3:$P$200=$A14)+($Q$3:$Q$200=$A14)+($R$3:$R$200=$A14)+($S$3:$S$200=$A14)+($T$3:$T$200=$A14)+($U$3:$U$200=$A14)+($V$3:$V$200=$A14)+($W$3:$W$200=$A14)+($X$3:$X$200=$A14)+($Y$3:$Y$200=$A14)+($Z$3:$Z$200=$A14)+($AA$3:$AA$200=$A14))>0)),$L$3:$L$200),"PENDIENTE"))} -> PENDIENTE | C14: {=IF($A14="","",IFERROR(LOOKUP(2,1/(($K$3:$K$200="Programación")*((($M$3:$M$200=$A14)+($N$3:$N$200=$A14)+($O$3:$O$200=$A14)+($P$3:$P$200=$A14)+($Q$3:$Q$200=$A14)+($R$3:$R$200=$A14)+($S$3:$S$200=$A14)+($T$3:$T$200=$A14)+($U$3:$U$200=$A14)+($V$3:$V$200=$A14)+($W$3:$W$200=$A14)+($X$3:$X$200=$A14)+($Y$3:$Y$200=$A14)+($Z$3:$Z$200=$A14)+($AA$3:$AA$200=$A14))>0)),$L$3:$L$200),"PENDIENTE"))} -> PENDIENTE | D14: {=IF($A14="","",IFERROR(LOOKUP(2,1/(($K$3:$K$200="Prueba PCB")*((($M$3:$M$200=$A14)+($N$3:$N$200=$A14)+($O$3:$O$200=$A14)+($P$3:$P$200=$A14)+($Q$3:$Q$200=$A14)+($R$3:$R$200=$A14)+($S$3:$S$200=$A14)+($T$3:$T$200=$A14)+($U$3:$U$200=$A14)+($V$3:$V$200=$A14)+($W$3:$W$200=$A14)+($X$3:$X$200=$A14)+($Y$3:$Y$200=$A14)+($Z$3:$Z$200=$A14)+($AA$3:$AA$200=$A14))>0)),$L$3:$L$200),"PENDIENTE"))} -> PENDIENTE | E14: {=IF($A14="","",IFERROR(LOOKUP(2,1/(($K$3:$K$200="Integración")*((($M$3:$M$200=$A14)+($N$3:$N$200=$A14)+($O$3:$O$200=$A14)+($P$3:$P$200=$A14)+($Q$3:$Q$200=$A14)+($R$3:$R$200=$A14)+($S$3:$S$200=$A14)+($T$3:$T$200=$A14)+($U$3:$U$200=$A14)+($V$3:$V$200=$A14)+($W$3:$W$200=$A14)+($X$3:$X$200=$A14)+($Y$3:$Y$200=$A14)+($Z$3:$Z$200=$A14)+($AA$3:$AA$200=$A14))>0)),$L$3:$L$200),"PENDIENTE"))} -> PENDIENTE | F14: {=IF($A14="","",IFERROR(LOOKUP(2,1/(($K$3:$K$200="Prueba Final")*((($M$3:$M$200=$A14)+($N$3:$N$200=$A14)+($O$3:$O$200=$A14)+($P$3:$P$200=$A14)+($Q$3:$Q$200=$A14)+($R$3:$R$200=$A14)+($S$3:$S$200=$A14)+($T$3:$T$200=$A14)+($U$3:$U$200=$A14)+($V$3:$V$200=$A14)+($W$3:$W$200=$A14)+($X$3:$X$200=$A14)+($Y$3:$Y$200=$A14)+($Z$3:$Z$200=$A14)+($AA$3:$AA$200=$A14))>0)),$L$3:$L$200),"PENDIENTE"))} -> PENDIENTE | G14: =IF($A14="","",IF(COUNTIF(B14:F14,"FALLA")>0,"DETENIDO",IF(COUNTIF(B14:F14,"RETRABAJO")>0,"RETRABAJO",IF(COUNTIF(B14:F14,"OK")+COUNTIF(B14:F14,"NO APLICA")=5,"LIBERADO",IF(COUNTIF(B14:F14,"PENDIENTE")=5,"PENDIENTE","EN PROCESO"))))) -> PENDIENTE
... A63: =IF(Producción!A63="","",Producción!A63) -> 0076 | B63: {=IF($A63="","",IFERROR(LOOKUP(2,1/(($K$3:$K$200="Soldadura")*((($M$3:$M$200=$A63)+($N$3:$N$200=$A63)+($O$3:$O$200=$A63)+($P$3:$P$200=$A63)+($Q$3:$Q$200=$A63)+($R$3:$R$200=$A63)+($S$3:$S$200=$A63)+($T$3:$T$200=$A63)+($U$3:$U$200=$A63)+($V$3:$V$200=$A63)+($W$3:$W$200=$A63)+($X$3:$X$200=$A63)+($Y$3:$Y$200=$A63)+($Z$3:$Z$200=$A63)+($AA$3:$AA$200=$A63))>0)),$L$3:$L$200),"PENDIENTE"))} -> PENDIENTE | C63: {=IF($A63="","",IFERROR(LOOKUP(2,1/(($K$3:$K$200="Programación")*((($M$3:$M$200=$A63)+($N$3:$N$200=$A63)+($O$3:$O$200=$A63)+($P$3:$P$200=$A63)+($Q$3:$Q$200=$A63)+($R$3:$R$200=$A63)+($S$3:$S$200=$A63)+($T$3:$T$200=$A63)+($U$3:$U$200=$A63)+($V$3:$V$200=$A63)+($W$3:$W$200=$A63)+($X$3:$X$200=$A63)+($Y$3:$Y$200=$A63)+($Z$3:$Z$200=$A63)+($AA$3:$AA$200=$A63))>0)),$L$3:$L$200),"PENDIENTE"))} -> PENDIENTE | D63: {=IF($A63="","",IFERROR(LOOKUP(2,1/(($K$3:$K$200="Prueba PCB")*((($M$3:$M$200=$A63)+($N$3:$N$200=$A63)+($O$3:$O$200=$A63)+($P$3:$P$200=$A63)+($Q$3:$Q$200=$A63)+($R$3:$R$200=$A63)+($S$3:$S$200=$A63)+($T$3:$T$200=$A63)+($U$3:$U$200=$A63)+($V$3:$V$200=$A63)+($W$3:$W$200=$A63)+($X$3:$X$200=$A63)+($Y$3:$Y$200=$A63)+($Z$3:$Z$200=$A63)+($AA$3:$AA$200=$A63))>0)),$L$3:$L$200),"PENDIENTE"))} -> PENDIENTE | E63: {=IF($A63="","",IFERROR(LOOKUP(2,1/(($K$3:$K$200="Integración")*((($M$3:$M$200=$A63)+($N$3:$N$200=$A63)+($O$3:$O$200=$A63)+($P$3:$P$200=$A63)+($Q$3:$Q$200=$A63)+($R$3:$R$200=$A63)+($S$3:$S$200=$A63)+($T$3:$T$200=$A63)+($U$3:$U$200=$A63)+($V$3:$V$200=$A63)+($W$3:$W$200=$A63)+($X$3:$X$200=$A63)+($Y$3:$Y$200=$A63)+($Z$3:$Z$200=$A63)+($AA$3:$AA$200=$A63))>0)),$L$3:$L$200),"PENDIENTE"))} -> PENDIENTE | F63: {=IF($A63="","",IFERROR(LOOKUP(2,1/(($K$3:$K$200="Prueba Final")*((($M$3:$M$200=$A63)+($N$3:$N$200=$A63)+($O$3:$O$200=$A63)+($P$3:$P$200=$A63)+($Q$3:$Q$200=$A63)+($R$3:$R$200=$A63)+($S$3:$S$200=$A63)+($T$3:$T$200=$A63)+($U$3:$U$200=$A63)+($V$3:$V$200=$A63)+($W$3:$W$200=$A63)+($X$3:$X$200=$A63)+($Y$3:$Y$200=$A63)+($Z$3:$Z$200=$A63)+($AA$3:$AA$200=$A63))>0)),$L$3:$L$200),"PENDIENTE"))} -> PENDIENTE | G63: =IF($A63="","",IF(COUNTIF(B63:F63,"FALLA")>0,"DETENIDO",IF(COUNTIF(B63:F63,"RETRABAJO")>0,"RETRABAJO",IF(COUNTIF(B63:F63,"OK")+COUNTIF(B63:F63,"NO APLICA")=5,"LIBERADO",IF(COUNTIF(B63:F63,"PENDIENTE")=5,"PENDIENTE","EN PROCESO"))))) -> PENDIENTE
A64: =IF(Producción!A64="","",Producción!A64) -> 0077 | B64: {=IF($A64="","",IFERROR(LOOKUP(2,1/(($K$3:$K$200="Soldadura")*((($M$3:$M$200=$A64)+($N$3:$N$200=$A64)+($O$3:$O$200=$A64)+($P$3:$P$200=$A64)+($Q$3:$Q$200=$A64)+($R$3:$R$200=$A64)+($S$3:$S$200=$A64)+($T$3:$T$200=$A64)+($U$3:$U$200=$A64)+($V$3:$V$200=$A64)+($W$3:$W$200=$A64)+($X$3:$X$200=$A64)+($Y$3:$Y$200=$A64)+($Z$3:$Z$200=$A64)+($AA$3:$AA$200=$A64))>0)),$L$3:$L$200),"PENDIENTE"))} -> PENDIENTE | C64: {=IF($A64="","",IFERROR(LOOKUP(2,1/(($K$3:$K$200="Programación")*((($M$3:$M$200=$A64)+($N$3:$N$200=$A64)+($O$3:$O$200=$A64)+($P$3:$P$200=$A64)+($Q$3:$Q$200=$A64)+($R$3:$R$200=$A64)+($S$3:$S$200=$A64)+($T$3:$T$200=$A64)+($U$3:$U$200=$A64)+($V$3:$V$200=$A64)+($W$3:$W$200=$A64)+($X$3:$X$200=$A64)+($Y$3:$Y$200=$A64)+($Z$3:$Z$200=$A64)+($AA$3:$AA$200=$A64))>0)),$L$3:$L$200),"PENDIENTE"))} -> PENDIENTE | D64: {=IF($A64="","",IFERROR(LOOKUP(2,1/(($K$3:$K$200="Prueba PCB")*((($M$3:$M$200=$A64)+($N$3:$N$200=$A64)+($O$3:$O$200=$A64)+($P$3:$P$200=$A64)+($Q$3:$Q$200=$A64)+($R$3:$R$200=$A64)+($S$3:$S$200=$A64)+($T$3:$T$200=$A64)+($U$3:$U$200=$A64)+($V$3:$V$200=$A64)+($W$3:$W$200=$A64)+($X$3:$X$200=$A64)+($Y$3:$Y$200=$A64)+($Z$3:$Z$200=$A64)+($AA$3:$AA$200=$A64))>0)),$L$3:$L$200),"PENDIENTE"))} -> PENDIENTE | E64: {=IF($A64="","",IFERROR(LOOKUP(2,1/(($K$3:$K$200="Integración")*((($M$3:$M$200=$A64)+($N$3:$N$200=$A64)+($O$3:$O$200=$A64)+($P$3:$P$200=$A64)+($Q$3:$Q$200=$A64)+($R$3:$R$200=$A64)+($S$3:$S$200=$A64)+($T$3:$T$200=$A64)+($U$3:$U$200=$A64)+($V$3:$V$200=$A64)+($W$3:$W$200=$A64)+($X$3:$X$200=$A64)+($Y$3:$Y$200=$A64)+($Z$3:$Z$200=$A64)+($AA$3:$AA$200=$A64))>0)),$L$3:$L$200),"PENDIENTE"))} -> PENDIENTE | F64: {=IF($A64="","",IFERROR(LOOKUP(2,1/(($K$3:$K$200="Prueba Final")*((($M$3:$M$200=$A64)+($N$3:$N$200=$A64)+($O$3:$O$200=$A64)+($P$3:$P$200=$A64)+($Q$3:$Q$200=$A64)+($R$3:$R$200=$A64)+($S$3:$S$200=$A64)+($T$3:$T$200=$A64)+($U$3:$U$200=$A64)+($V$3:$V$200=$A64)+($W$3:$W$200=$A64)+($X$3:$X$200=$A64)+($Y$3:$Y$200=$A64)+($Z$3:$Z$200=$A64)+($AA$3:$AA$200=$A64))>0)),$L$3:$L$200),"PENDIENTE"))} -> PENDIENTE | G64: =IF($A64="","",IF(COUNTIF(B64:F64,"FALLA")>0,"DETENIDO",IF(COUNTIF(B64:F64,"RETRABAJO")>0,"RETRABAJO",IF(COUNTIF(B64:F64,"OK")+COUNTIF(B64:F64,"NO APLICA")=5,"LIBERADO",IF(COUNTIF(B64:F64,"PENDIENTE")=5,"PENDIENTE","EN PROCESO"))))) -> PENDIENTE | J64: Una fila = una actualización. Elige Proceso + Estatus y selecciona de 1 a 15 IDs. Si luego vuelves a registrar la misma tarjeta/proceso en una fila inferior, prevalece el último estatus.
A65: =IF(Producción!A65="","",Producción!A65) -> 0079 | B65: {=IF($A65="","",IFERROR(LOOKUP(2,1/(($K$3:$K$200="Soldadura")*((($M$3:$M$200=$A65)+($N$3:$N$200=$A65)+($O$3:$O$200=$A65)+($P$3:$P$200=$A65)+($Q$3:$Q$200=$A65)+($R$3:$R$200=$A65)+($S$3:$S$200=$A65)+($T$3:$T$200=$A65)+($U$3:$U$200=$A65)+($V$3:$V$200=$A65)+($W$3:$W$200=$A65)+($X$3:$X$200=$A65)+($Y$3:$Y$200=$A65)+($Z$3:$Z$200=$A65)+($AA$3:$AA$200=$A65))>0)),$L$3:$L$200),"PENDIENTE"))} -> PENDIENTE | C65: {=IF($A65="","",IFERROR(LOOKUP(2,1/(($K$3:$K$200="Programación")*((($M$3:$M$200=$A65)+($N$3:$N$200=$A65)+($O$3:$O$200=$A65)+($P$3:$P$200=$A65)+($Q$3:$Q$200=$A65)+($R$3:$R$200=$A65)+($S$3:$S$200=$A65)+($T$3:$T$200=$A65)+($U$3:$U$200=$A65)+($V$3:$V$200=$A65)+($W$3:$W$200=$A65)+($X$3:$X$200=$A65)+($Y$3:$Y$200=$A65)+($Z$3:$Z$200=$A65)+($AA$3:$AA$200=$A65))>0)),$L$3:$L$200),"PENDIENTE"))} -> PENDIENTE | D65: {=IF($A65="","",IFERROR(LOOKUP(2,1/(($K$3:$K$200="Prueba PCB")*((($M$3:$M$200=$A65)+($N$3:$N$200=$A65)+($O$3:$O$200=$A65)+($P$3:$P$200=$A65)+($Q$3:$Q$200=$A65)+($R$3:$R$200=$A65)+($S$3:$S$200=$A65)+($T$3:$T$200=$A65)+($U$3:$U$200=$A65)+($V$3:$V$200=$A65)+($W$3:$W$200=$A65)+($X$3:$X$200=$A65)+($Y$3:$Y$200=$A65)+($Z$3:$Z$200=$A65)+($AA$3:$AA$200=$A65))>0)),$L$3:$L$200),"PENDIENTE"))} -> PENDIENTE | E65: {=IF($A65="","",IFERROR(LOOKUP(2,1/(($K$3:$K$200="Integración")*((($M$3:$M$200=$A65)+($N$3:$N$200=$A65)+($O$3:$O$200=$A65)+($P$3:$P$200=$A65)+($Q$3:$Q$200=$A65)+($R$3:$R$200=$A65)+($S$3:$S$200=$A65)+($T$3:$T$200=$A65)+($U$3:$U$200=$A65)+($V$3:$V$200=$A65)+($W$3:$W$200=$A65)+($X$3:$X$200=$A65)+($Y$3:$Y$200=$A65)+($Z$3:$Z$200=$A65)+($AA$3:$AA$200=$A65))>0)),$L$3:$L$200),"PENDIENTE"))} -> PENDIENTE | F65: {=IF($A65="","",IFERROR(LOOKUP(2,1/(($K$3:$K$200="Prueba Final")*((($M$3:$M$200=$A65)+($N$3:$N$200=$A65)+($O$3:$O$200=$A65)+($P$3:$P$200=$A65)+($Q$3:$Q$200=$A65)+($R$3:$R$200=$A65)+($S$3:$S$200=$A65)+($T$3:$T$200=$A65)+($U$3:$U$200=$A65)+($V$3:$V$200=$A65)+($W$3:$W$200=$A65)+($X$3:$X$200=$A65)+($Y$3:$Y$200=$A65)+($Z$3:$Z$200=$A65)+($AA$3:$AA$200=$A65))>0)),$L$3:$L$200),"PENDIENTE"))} -> PENDIENTE | G65: =IF($A65="","",IF(COUNTIF(B65:F65,"FALLA")>0,"DETENIDO",IF(COUNTIF(B65:F65,"RETRABAJO")>0,"RETRABAJO",IF(COUNTIF(B65:F65,"OK")+COUNTIF(B65:F65,"NO APLICA")=5,"LIBERADO",IF(COUNTIF(B65:F65,"PENDIENTE")=5,"PENDIENTE","EN PROCESO"))))) -> PENDIENTE
A66: =IF(Producción!A66="","",Producción!A66) -> 0080 | B66: {=IF($A66="","",IFERROR(LOOKUP(2,1/(($K$3:$K$200="Soldadura")*((($M$3:$M$200=$A66)+($N$3:$N$200=$A66)+($O$3:$O$200=$A66)+($P$3:$P$200=$A66)+($Q$3:$Q$200=$A66)+($R$3:$R$200=$A66)+($S$3:$S$200=$A66)+($T$3:$T$200=$A66)+($U$3:$U$200=$A66)+($V$3:$V$200=$A66)+($W$3:$W$200=$A66)+($X$3:$X$200=$A66)+($Y$3:$Y$200=$A66)+($Z$3:$Z$200=$A66)+($AA$3:$AA$200=$A66))>0)),$L$3:$L$200),"PENDIENTE"))} -> PENDIENTE | C66: {=IF($A66="","",IFERROR(LOOKUP(2,1/(($K$3:$K$200="Programación")*((($M$3:$M$200=$A66)+($N$3:$N$200=$A66)+($O$3:$O$200=$A66)+($P$3:$P$200=$A66)+($Q$3:$Q$200=$A66)+($R$3:$R$200=$A66)+($S$3:$S$200=$A66)+($T$3:$T$200=$A66)+($U$3:$U$200=$A66)+($V$3:$V$200=$A66)+($W$3:$W$200=$A66)+($X$3:$X$200=$A66)+($Y$3:$Y$200=$A66)+($Z$3:$Z$200=$A66)+($AA$3:$AA$200=$A66))>0)),$L$3:$L$200),"PENDIENTE"))} -> PENDIENTE | D66: {=IF($A66="","",IFERROR(LOOKUP(2,1/(($K$3:$K$200="Prueba PCB")*((($M$3:$M$200=$A66)+($N$3:$N$200=$A66)+($O$3:$O$200=$A66)+($P$3:$P$200=$A66)+($Q$3:$Q$200=$A66)+($R$3:$R$200=$A66)+($S$3:$S$200=$A66)+($T$3:$T$200=$A66)+($U$3:$U$200=$A66)+($V$3:$V$200=$A66)+($W$3:$W$200=$A66)+($X$3:$X$200=$A66)+($Y$3:$Y$200=$A66)+($Z$3:$Z$200=$A66)+($AA$3:$AA$200=$A66))>0)),$L$3:$L$200),"PENDIENTE"))} -> PENDIENTE | E66: {=IF($A66="","",IFERROR(LOOKUP(2,1/(($K$3:$K$200="Integración")*((($M$3:$M$200=$A66)+($N$3:$N$200=$A66)+($O$3:$O$200=$A66)+($P$3:$P$200=$A66)+($Q$3:$Q$200=$A66)+($R$3:$R$200=$A66)+($S$3:$S$200=$A66)+($T$3:$T$200=$A66)+($U$3:$U$200=$A66)+($V$3:$V$200=$A66)+($W$3:$W$200=$A66)+($X$3:$X$200=$A66)+($Y$3:$Y$200=$A66)+($Z$3:$Z$200=$A66)+($AA$3:$AA$200=$A66))>0)),$L$3:$L$200),"PENDIENTE"))} -> PENDIENTE | F66: {=IF($A66="","",IFERROR(LOOKUP(2,1/(($K$3:$K$200="Prueba Final")*((($M$3:$M$200=$A66)+($N$3:$N$200=$A66)+($O$3:$O$200=$A66)+($P$3:$P$200=$A66)+($Q$3:$Q$200=$A66)+($R$3:$R$200=$A66)+($S$3:$S$200=$A66)+($T$3:$T$200=$A66)+($U$3:$U$200=$A66)+($V$3:$V$200=$A66)+($W$3:$W$200=$A66)+($X$3:$X$200=$A66)+($Y$3:$Y$200=$A66)+($Z$3:$Z$200=$A66)+($AA$3:$AA$200=$A66))>0)),$L$3:$L$200),"PENDIENTE"))} -> PENDIENTE | G66: =IF($A66="","",IF(COUNTIF(B66:F66,"FALLA")>0,"DETENIDO",IF(COUNTIF(B66:F66,"RETRABAJO")>0,"RETRABAJO",IF(COUNTIF(B66:F66,"OK")+COUNTIF(B66:F66,"NO APLICA")=5,"LIBERADO",IF(COUNTIF(B66:F66,"PENDIENTE")=5,"PENDIENTE","EN PROCESO"))))) -> PENDIENTE
A67: =IF(Producción!A67="","",Producción!A67) -> 0081 | B67: {=IF($A67="","",IFERROR(LOOKUP(2,1/(($K$3:$K$200="Soldadura")*((($M$3:$M$200=$A67)+($N$3:$N$200=$A67)+($O$3:$O$200=$A67)+($P$3:$P$200=$A67)+($Q$3:$Q$200=$A67)+($R$3:$R$200=$A67)+($S$3:$S$200=$A67)+($T$3:$T$200=$A67)+($U$3:$U$200=$A67)+($V$3:$V$200=$A67)+($W$3:$W$200=$A67)+($X$3:$X$200=$A67)+($Y$3:$Y$200=$A67)+($Z$3:$Z$200=$A67)+($AA$3:$AA$200=$A67))>0)),$L$3:$L$200),"PENDIENTE"))} -> PENDIENTE | C67: {=IF($A67="","",IFERROR(LOOKUP(2,1/(($K$3:$K$200="Programación")*((($M$3:$M$200=$A67)+($N$3:$N$200=$A67)+($O$3:$O$200=$A67)+($P$3:$P$200=$A67)+($Q$3:$Q$200=$A67)+($R$3:$R$200=$A67)+($S$3:$S$200=$A67)+($T$3:$T$200=$A67)+($U$3:$U$200=$A67)+($V$3:$V$200=$A67)+($W$3:$W$200=$A67)+($X$3:$X$200=$A67)+($Y$3:$Y$200=$A67)+($Z$3:$Z$200=$A67)+($AA$3:$AA$200=$A67))>0)),$L$3:$L$200),"PENDIENTE"))} -> PENDIENTE | D67: {=IF($A67="","",IFERROR(LOOKUP(2,1/(($K$3:$K$200="Prueba PCB")*((($M$3:$M$200=$A67)+($N$3:$N$200=$A67)+($O$3:$O$200=$A67)+($P$3:$P$200=$A67)+($Q$3:$Q$200=$A67)+($R$3:$R$200=$A67)+($S$3:$S$200=$A67)+($T$3:$T$200=$A67)+($U$3:$U$200=$A67)+($V$3:$V$200=$A67)+($W$3:$W$200=$A67)+($X$3:$X$200=$A67)+($Y$3:$Y$200=$A67)+($Z$3:$Z$200=$A67)+($AA$3:$AA$200=$A67))>0)),$L$3:$L$200),"PENDIENTE"))} -> PENDIENTE | E67: {=IF($A67="","",IFERROR(LOOKUP(2,1/(($K$3:$K$200="Integración")*((($M$3:$M$200=$A67)+($N$3:$N$200=$A67)+($O$3:$O$200=$A67)+($P$3:$P$200=$A67)+($Q$3:$Q$200=$A67)+($R$3:$R$200=$A67)+($S$3:$S$200=$A67)+($T$3:$T$200=$A67)+($U$3:$U$200=$A67)+($V$3:$V$200=$A67)+($W$3:$W$200=$A67)+($X$3:$X$200=$A67)+($Y$3:$Y$200=$A67)+($Z$3:$Z$200=$A67)+($AA$3:$AA$200=$A67))>0)),$L$3:$L$200),"PENDIENTE"))} -> PENDIENTE | F67: {=IF($A67="","",IFERROR(LOOKUP(2,1/(($K$3:$K$200="Prueba Final")*((($M$3:$M$200=$A67)+($N$3:$N$200=$A67)+($O$3:$O$200=$A67)+($P$3:$P$200=$A67)+($Q$3:$Q$200=$A67)+($R$3:$R$200=$A67)+($S$3:$S$200=$A67)+($T$3:$T$200=$A67)+($U$3:$U$200=$A67)+($V$3:$V$200=$A67)+($W$3:$W$200=$A67)+($X$3:$X$200=$A67)+($Y$3:$Y$200=$A67)+($Z$3:$Z$200=$A67)+($AA$3:$AA$200=$A67))>0)),$L$3:$L$200),"PENDIENTE"))} -> PENDIENTE | G67: =IF($A67="","",IF(COUNTIF(B67:F67,"FALLA")>0,"DETENIDO",IF(COUNTIF(B67:F67,"RETRABAJO")>0,"RETRABAJO",IF(COUNTIF(B67:F67,"OK")+COUNTIF(B67:F67,"NO APLICA")=5,"LIBERADO",IF(COUNTIF(B67:F67,"PENDIENTE")=5,"PENDIENTE","EN PROCESO"))))) -> PENDIENTE
A68: =IF(Producción!A68="","",Producción!A68) -> 0083 | B68: {=IF($A68="","",IFERROR(LOOKUP(2,1/(($K$3:$K$200="Soldadura")*((($M$3:$M$200=$A68)+($N$3:$N$200=$A68)+($O$3:$O$200=$A68)+($P$3:$P$200=$A68)+($Q$3:$Q$200=$A68)+($R$3:$R$200=$A68)+($S$3:$S$200=$A68)+($T$3:$T$200=$A68)+($U$3:$U$200=$A68)+($V$3:$V$200=$A68)+($W$3:$W$200=$A68)+($X$3:$X$200=$A68)+($Y$3:$Y$200=$A68)+($Z$3:$Z$200=$A68)+($AA$3:$AA$200=$A68))>0)),$L$3:$L$200),"PENDIENTE"))} -> PENDIENTE | C68: {=IF($A68="","",IFERROR(LOOKUP(2,1/(($K$3:$K$200="Programación")*((($M$3:$M$200=$A68)+($N$3:$N$200=$A68)+($O$3:$O$200=$A68)+($P$3:$P$200=$A68)+($Q$3:$Q$200=$A68)+($R$3:$R$200=$A68)+($S$3:$S$200=$A68)+($T$3:$T$200=$A68)+($U$3:$U$200=$A68)+($V$3:$V$200=$A68)+($W$3:$W$200=$A68)+($X$3:$X$200=$A68)+($Y$3:$Y$200=$A68)+($Z$3:$Z$200=$A68)+($AA$3:$AA$200=$A68))>0)),$L$3:$L$200),"PENDIENTE"))} -> PENDIENTE | D68: {=IF($A68="","",IFERROR(LOOKUP(2,1/(($K$3:$K$200="Prueba PCB")*((($M$3:$M$200=$A68)+($N$3:$N$200=$A68)+($O$3:$O$200=$A68)+($P$3:$P$200=$A68)+($Q$3:$Q$200=$A68)+($R$3:$R$200=$A68)+($S$3:$S$200=$A68)+($T$3:$T$200=$A68)+($U$3:$U$200=$A68)+($V$3:$V$200=$A68)+($W$3:$W$200=$A68)+($X$3:$X$200=$A68)+($Y$3:$Y$200=$A68)+($Z$3:$Z$200=$A68)+($AA$3:$AA$200=$A68))>0)),$L$3:$L$200),"PENDIENTE"))} -> PENDIENTE | E68: {=IF($A68="","",IFERROR(LOOKUP(2,1/(($K$3:$K$200="Integración")*((($M$3:$M$200=$A68)+($N$3:$N$200=$A68)+($O$3:$O$200=$A68)+($P$3:$P$200=$A68)+($Q$3:$Q$200=$A68)+($R$3:$R$200=$A68)+($S$3:$S$200=$A68)+($T$3:$T$200=$A68)+($U$3:$U$200=$A68)+($V$3:$V$200=$A68)+($W$3:$W$200=$A68)+($X$3:$X$200=$A68)+($Y$3:$Y$200=$A68)+($Z$3:$Z$200=$A68)+($AA$3:$AA$200=$A68))>0)),$L$3:$L$200),"PENDIENTE"))} -> PENDIENTE | F68: {=IF($A68="","",IFERROR(LOOKUP(2,1/(($K$3:$K$200="Prueba Final")*((($M$3:$M$200=$A68)+($N$3:$N$200=$A68)+($O$3:$O$200=$A68)+($P$3:$P$200=$A68)+($Q$3:$Q$200=$A68)+($R$3:$R$200=$A68)+($S$3:$S$200=$A68)+($T$3:$T$200=$A68)+($U$3:$U$200=$A68)+($V$3:$V$200=$A68)+($W$3:$W$200=$A68)+($X$3:$X$200=$A68)+($Y$3:$Y$200=$A68)+($Z$3:$Z$200=$A68)+($AA$3:$AA$200=$A68))>0)),$L$3:$L$200),"PENDIENTE"))} -> PENDIENTE | G68: =IF($A68="","",IF(COUNTIF(B68:F68,"FALLA")>0,"DETENIDO",IF(COUNTIF(B68:F68,"RETRABAJO")>0,"RETRABAJO",IF(COUNTIF(B68:F68,"OK")+COUNTIF(B68:F68,"NO APLICA")=5,"LIBERADO",IF(COUNTIF(B68:F68,"PENDIENTE")=5,"PENDIENTE","EN PROCESO"))))) -> PENDIENTE
A69: =IF(Producción!A69="","",Producción!A69) -> 0084 | B69: {=IF($A69="","",IFERROR(LOOKUP(2,1/(($K$3:$K$200="Soldadura")*((($M$3:$M$200=$A69)+($N$3:$N$200=$A69)+($O$3:$O$200=$A69)+($P$3:$P$200=$A69)+($Q$3:$Q$200=$A69)+($R$3:$R$200=$A69)+($S$3:$S$200=$A69)+($T$3:$T$200=$A69)+($U$3:$U$200=$A69)+($V$3:$V$200=$A69)+($W$3:$W$200=$A69)+($X$3:$X$200=$A69)+($Y$3:$Y$200=$A69)+($Z$3:$Z$200=$A69)+($AA$3:$AA$200=$A69))>0)),$L$3:$L$200),"PENDIENTE"))} -> PENDIENTE | C69: {=IF($A69="","",IFERROR(LOOKUP(2,1/(($K$3:$K$200="Programación")*((($M$3:$M$200=$A69)+($N$3:$N$200=$A69)+($O$3:$O$200=$A69)+($P$3:$P$200=$A69)+($Q$3:$Q$200=$A69)+($R$3:$R$200=$A69)+($S$3:$S$200=$A69)+($T$3:$T$200=$A69)+($U$3:$U$200=$A69)+($V$3:$V$200=$A69)+($W$3:$W$200=$A69)+($X$3:$X$200=$A69)+($Y$3:$Y$200=$A69)+($Z$3:$Z$200=$A69)+($AA$3:$AA$200=$A69))>0)),$L$3:$L$200),"PENDIENTE"))} -> PENDIENTE | D69: {=IF($A69="","",IFERROR(LOOKUP(2,1/(($K$3:$K$200="Prueba PCB")*((($M$3:$M$200=$A69)+($N$3:$N$200=$A69)+($O$3:$O$200=$A69)+($P$3:$P$200=$A69)+($Q$3:$Q$200=$A69)+($R$3:$R$200=$A69)+($S$3:$S$200=$A69)+($T$3:$T$200=$A69)+($U$3:$U$200=$A69)+($V$3:$V$200=$A69)+($W$3:$W$200=$A69)+($X$3:$X$200=$A69)+($Y$3:$Y$200=$A69)+($Z$3:$Z$200=$A69)+($AA$3:$AA$200=$A69))>0)),$L$3:$L$200),"PENDIENTE"))} -> PENDIENTE | E69: {=IF($A69="","",IFERROR(LOOKUP(2,1/(($K$3:$K$200="Integración")*((($M$3:$M$200=$A69)+($N$3:$N$200=$A69)+($O$3:$O$200=$A69)+($P$3:$P$200=$A69)+($Q$3:$Q$200=$A69)+($R$3:$R$200=$A69)+($S$3:$S$200=$A69)+($T$3:$T$200=$A69)+($U$3:$U$200=$A69)+($V$3:$V$200=$A69)+($W$3:$W$200=$A69)+($X$3:$X$200=$A69)+($Y$3:$Y$200=$A69)+($Z$3:$Z$200=$A69)+($AA$3:$AA$200=$A69))>0)),$L$3:$L$200),"PENDIENTE"))} -> PENDIENTE | F69: {=IF($A69="","",IFERROR(LOOKUP(2,1/(($K$3:$K$200="Prueba Final")*((($M$3:$M$200=$A69)+($N$3:$N$200=$A69)+($O$3:$O$200=$A69)+($P$3:$P$200=$A69)+($Q$3:$Q$200=$A69)+($R$3:$R$200=$A69)+($S$3:$S$200=$A69)+($T$3:$T$200=$A69)+($U$3:$U$200=$A69)+($V$3:$V$200=$A69)+($W$3:$W$200=$A69)+($X$3:$X$200=$A69)+($Y$3:$Y$200=$A69)+($Z$3:$Z$200=$A69)+($AA$3:$AA$200=$A69))>0)),$L$3:$L$200),"PENDIENTE"))} -> PENDIENTE | G69: =IF($A69="","",IF(COUNTIF(B69:F69,"FALLA")>0,"DETENIDO",IF(COUNTIF(B69:F69,"RETRABAJO")>0,"RETRABAJO",IF(COUNTIF(B69:F69,"OK")+COUNTIF(B69:F69,"NO APLICA")=5,"LIBERADO",IF(COUNTIF(B69:F69,"PENDIENTE")=5,"PENDIENTE","EN PROCESO"))))) -> PENDIENTE
A70: =IF(Producción!A70="","",Producción!A70) -> 0085 | B70: {=IF($A70="","",IFERROR(LOOKUP(2,1/(($K$3:$K$200="Soldadura")*((($M$3:$M$200=$A70)+($N$3:$N$200=$A70)+($O$3:$O$200=$A70)+($P$3:$P$200=$A70)+($Q$3:$Q$200=$A70)+($R$3:$R$200=$A70)+($S$3:$S$200=$A70)+($T$3:$T$200=$A70)+($U$3:$U$200=$A70)+($V$3:$V$200=$A70)+($W$3:$W$200=$A70)+($X$3:$X$200=$A70)+($Y$3:$Y$200=$A70)+($Z$3:$Z$200=$A70)+($AA$3:$AA$200=$A70))>0)),$L$3:$L$200),"PENDIENTE"))} -> PENDIENTE | C70: {=IF($A70="","",IFERROR(LOOKUP(2,1/(($K$3:$K$200="Programación")*((($M$3:$M$200=$A70)+($N$3:$N$200=$A70)+($O$3:$O$200=$A70)+($P$3:$P$200=$A70)+($Q$3:$Q$200=$A70)+($R$3:$R$200=$A70)+($S$3:$S$200=$A70)+($T$3:$T$200=$A70)+($U$3:$U$200=$A70)+($V$3:$V$200=$A70)+($W$3:$W$200=$A70)+($X$3:$X$200=$A70)+($Y$3:$Y$200=$A70)+($Z$3:$Z$200=$A70)+($AA$3:$AA$200=$A70))>0)),$L$3:$L$200),"PENDIENTE"))} -> PENDIENTE | D70: {=IF($A70="","",IFERROR(LOOKUP(2,1/(($K$3:$K$200="Prueba PCB")*((($M$3:$M$200=$A70)+($N$3:$N$200=$A70)+($O$3:$O$200=$A70)+($P$3:$P$200=$A70)+($Q$3:$Q$200=$A70)+($R$3:$R$200=$A70)+($S$3:$S$200=$A70)+($T$3:$T$200=$A70)+($U$3:$U$200=$A70)+($V$3:$V$200=$A70)+($W$3:$W$200=$A70)+($X$3:$X$200=$A70)+($Y$3:$Y$200=$A70)+($Z$3:$Z$200=$A70)+($AA$3:$AA$200=$A70))>0)),$L$3:$L$200),"PENDIENTE"))} -> PENDIENTE | E70: {=IF($A70="","",IFERROR(LOOKUP(2,1/(($K$3:$K$200="Integración")*((($M$3:$M$200=$A70)+($N$3:$N$200=$A70)+($O$3:$O$200=$A70)+($P$3:$P$200=$A70)+($Q$3:$Q$200=$A70)+($R$3:$R$200=$A70)+($S$3:$S$200=$A70)+($T$3:$T$200=$A70)+($U$3:$U$200=$A70)+($V$3:$V$200=$A70)+($W$3:$W$200=$A70)+($X$3:$X$200=$A70)+($Y$3:$Y$200=$A70)+($Z$3:$Z$200=$A70)+($AA$3:$AA$200=$A70))>0)),$L$3:$L$200),"PENDIENTE"))} -> PENDIENTE | F70: {=IF($A70="","",IFERROR(LOOKUP(2,1/(($K$3:$K$200="Prueba Final")*((($M$3:$M$200=$A70)+($N$3:$N$200=$A70)+($O$3:$O$200=$A70)+($P$3:$P$200=$A70)+($Q$3:$Q$200=$A70)+($R$3:$R$200=$A70)+($S$3:$S$200=$A70)+($T$3:$T$200=$A70)+($U$3:$U$200=$A70)+($V$3:$V$200=$A70)+($W$3:$W$200=$A70)+($X$3:$X$200=$A70)+($Y$3:$Y$200=$A70)+($Z$3:$Z$200=$A70)+($AA$3:$AA$200=$A70))>0)),$L$3:$L$200),"PENDIENTE"))} -> PENDIENTE | G70: =IF($A70="","",IF(COUNTIF(B70:F70,"FALLA")>0,"DETENIDO",IF(COUNTIF(B70:F70,"RETRABAJO")>0,"RETRABAJO",IF(COUNTIF(B70:F70,"OK")+COUNTIF(B70:F70,"NO APLICA")=5,"LIBERADO",IF(COUNTIF(B70:F70,"PENDIENTE")=5,"PENDIENTE","EN PROCESO"))))) -> PENDIENTE
A71: =IF(Producción!A71="","",Producción!A71) -> 0086 | B71: {=IF($A71="","",IFERROR(LOOKUP(2,1/(($K$3:$K$200="Soldadura")*((($M$3:$M$200=$A71)+($N$3:$N$200=$A71)+($O$3:$O$200=$A71)+($P$3:$P$200=$A71)+($Q$3:$Q$200=$A71)+($R$3:$R$200=$A71)+($S$3:$S$200=$A71)+($T$3:$T$200=$A71)+($U$3:$U$200=$A71)+($V$3:$V$200=$A71)+($W$3:$W$200=$A71)+($X$3:$X$200=$A71)+($Y$3:$Y$200=$A71)+($Z$3:$Z$200=$A71)+($AA$3:$AA$200=$A71))>0)),$L$3:$L$200),"PENDIENTE"))} -> PENDIENTE | C71: {=IF($A71="","",IFERROR(LOOKUP(2,1/(($K$3:$K$200="Programación")*((($M$3:$M$200=$A71)+($N$3:$N$200=$A71)+($O$3:$O$200=$A71)+($P$3:$P$200=$A71)+($Q$3:$Q$200=$A71)+($R$3:$R$200=$A71)+($S$3:$S$200=$A71)+($T$3:$T$200=$A71)+($U$3:$U$200=$A71)+($V$3:$V$200=$A71)+($W$3:$W$200=$A71)+($X$3:$X$200=$A71)+($Y$3:$Y$200=$A71)+($Z$3:$Z$200=$A71)+($AA$3:$AA$200=$A71))>0)),$L$3:$L$200),"PENDIENTE"))} -> PENDIENTE | D71: {=IF($A71="","",IFERROR(LOOKUP(2,1/(($K$3:$K$200="Prueba PCB")*((($M$3:$M$200=$A71)+($N$3:$N$200=$A71)+($O$3:$O$200=$A71)+($P$3:$P$200=$A71)+($Q$3:$Q$200=$A71)+($R$3:$R$200=$A71)+($S$3:$S$200=$A71)+($T$3:$T$200=$A71)+($U$3:$U$200=$A71)+($V$3:$V$200=$A71)+($W$3:$W$200=$A71)+($X$3:$X$200=$A71)+($Y$3:$Y$200=$A71)+($Z$3:$Z$200=$A71)+($AA$3:$AA$200=$A71))>0)),$L$3:$L$200),"PENDIENTE"))} -> PENDIENTE | E71: {=IF($A71="","",IFERROR(LOOKUP(2,1/(($K$3:$K$200="Integración")*((($M$3:$M$200=$A71)+($N$3:$N$200=$A71)+($O$3:$O$200=$A71)+($P$3:$P$200=$A71)+($Q$3:$Q$200=$A71)+($R$3:$R$200=$A71)+($S$3:$S$200=$A71)+($T$3:$T$200=$A71)+($U$3:$U$200=$A71)+($V$3:$V$200=$A71)+($W$3:$W$200=$A71)+($X$3:$X$200=$A71)+($Y$3:$Y$200=$A71)+($Z$3:$Z$200=$A71)+($AA$3:$AA$200=$A71))>0)),$L$3:$L$200),"PENDIENTE"))} -> PENDIENTE | F71: {=IF($A71="","",IFERROR(LOOKUP(2,1/(($K$3:$K$200="Prueba Final")*((($M$3:$M$200=$A71)+($N$3:$N$200=$A71)+($O$3:$O$200=$A71)+($P$3:$P$200=$A71)+($Q$3:$Q$200=$A71)+($R$3:$R$200=$A71)+($S$3:$S$200=$A71)+($T$3:$T$200=$A71)+($U$3:$U$200=$A71)+($V$3:$V$200=$A71)+($W$3:$W$200=$A71)+($X$3:$X$200=$A71)+($Y$3:$Y$200=$A71)+($Z$3:$Z$200=$A71)+($AA$3:$AA$200=$A71))>0)),$L$3:$L$200),"PENDIENTE"))} -> PENDIENTE | G71: =IF($A71="","",IF(COUNTIF(B71:F71,"FALLA")>0,"DETENIDO",IF(COUNTIF(B71:F71,"RETRABAJO")>0,"RETRABAJO",IF(COUNTIF(B71:F71,"OK")+COUNTIF(B71:F71,"NO APLICA")=5,"LIBERADO",IF(COUNTIF(B71:F71,"PENDIENTE")=5,"PENDIENTE","EN PROCESO"))))) -> PENDIENTE
